Workbook

Sheet Parameters
A1: HHI vs 損失率 Monte Carlo分析（数式版）
A3: パラメータ | B3: 値 | C3: 説明
A4: PD (デフォルト確率) | B4: 0.0003 | C4: AA格の年間PD（編集可）
A5: LGD (損失率) | B5: 1 | C5: デフォルト時の損失割合（編集可）
A6: シミュレーション回数 | B6: 500 | C6: 試行回数（500列）
A7: 債務者数 | B7: 10 | C7: ポートフォリオの企業数
A9: 使い方
A10: 1. Weightsシートで各シナリオの債務者ウェイトを編集
A11: 2. PD・LGDはこのシートのB4・B5で変更可能
A12: 3. F9キー（またはCtrl+Alt+F9）で再シミュレーション
A13: 4. Resultsシートで各シナリオのHHI・損失指標・チャートを確認
A14: 5. 全ての計算はExcel数式 — VBAなし

Sheet Weights
A1: 債務者ウェイト配分（各シナリオ）
A2: ※黄色セルは編集可能。ウェイトの合計は100%になるようにしてください。
A4: シナリオ | B4: 債務者1 | C4: 債務者2 | D4: 債務者3 | E4: 債務者4 | F4: 債務者5 | G4: 債務者6 | H4: 債務者7 | I4: 債務者8 | J4: 債務者9 | K4: 債務者10 | L4: 合計 | M4: HHI
A5: 均等配分 | B5: 0.1 | C5: 0.1 | D5: 0.1 | E5: 0.1 | F5: 0.1 | G5: 0.1 | H5: 0.1 | I5: 0.1 | J5: 0.1 | K5: 0.1 | L5: =SUM(B5:K5) | M5: =SUMPRODUCT(B5:K5,B5:K5)
A6: やや集中 | B6: 0.2 | C6: 0.15 | D6: 0.12 | E6: 0.11 | F6: 0.1 | G6: 0.08 | H6: 0.08 | I6: 0.07 | J6: 0.05 | K6: 0.04 | L6: =SUM(B6:K6) | M6: =SUMPRODUCT(B6:K6,B6:K6)
A7: 中程度集中 | B7: 0.3 | C7: 0.2 | D7: 0.15 | E7: 0.1 | F7: 0.08 | G7: 0.05 | H7: 0.05 | I7: 0.03 | J7: 0.02 | K7: 0.02 | L7: =SUM(B7:K7) | M7: =SUMPRODUCT(B7:K7,B7:K7)
A8: 高集中 | B8: 0.5 | C8: 0.15 | D8: 0.1 | E8: 0.07 | F8: 0.05 | G8: 0.04 | H8: 0.03 | I8: 0.03 | J8: 0.02 | K8: 0.01 | L8: =SUM(B8:K8) | M8: =SUMPRODUCT(B8:K8,B8:K8)
A9: 極端な集中 | B9: 0.7 | C9: 0.1 | D9: 0.05 | E9: 0.04 | F9: 0.03 | G9: 0.02 | H9: 0.02 | I9: 0.02 | J9: 0.01 | K9: 0.01 | L9: =SUM(B9:K9) | M9: =SUMPRODUCT(B9:K9,B9:K9)
A10: 1社集中 | B10: 0.91 | C10: 0.01 | D10: 0.01 | E10: 0.01 | F10: 0.01 | G10: 0.01 | H10: 0.01 | I10: 0.01 | J10: 0.01 | K10: 0.01 | L10: =SUM(B10:K10) | M10: =SUMPRODUCT(B10:K10,B10:K10)

Sheet Sim_1_均等配分
A1: 債務者 \ Trial | B1: Trial 1 | C1: Trial 2 | D1: Trial 3 | E1: Trial 4 | F1: Trial 5 | G1: Trial 6 | H1: Trial 7 | I1: Trial 8 | J1: Trial 9 | K1: Trial 10 | L1: Trial 11 | M1: Trial 12 | N1: Trial 13 | O1: Trial 14 | P1: Trial 15 | Q1: Trial 16 | R1: Trial 17 | S1: Trial 18 | T1: Trial 19 | U1: Trial 20 | V1: Trial 21 | W1: Trial 22 | X1: Trial 23 | Y1: Trial 24 | Z1: Trial 25 | AA1: Trial 26 | AB1: Trial 27 | AC1: Trial 28 | AD1: Trial 29 | AE1: Trial 30 | AF1: Trial 31 | AG1: Trial 32 | AH1: Trial 33 | AI1: Trial 34 | AJ1: Trial 35 | AK1: Trial 36 | AL1: Trial 37 | AM1: Trial 38 | AN1: Trial 39 | AO1: Trial 40 | AP1: Trial 41 | AQ1: Trial 42 | AR1: Trial 43 | AS1: Trial 44 | AT1: Trial 45 | AU1: Trial 46 | AV1: Trial 47 | AW1: Trial 48 | AX1: Trial 49 | AY1: Trial 50 | AZ1: Trial 51 | BA1: Trial 52 | BB1: Trial 53 | BC1: Trial 54 | BD1: Trial 55 | BE1: Trial 56 | BF1: Trial 57 | BG1: Trial 58 | BH1: Trial 59 | BI1: Trial 60 | BJ1: Trial 61 | BK1: Trial 62 | BL1: Trial 63 | BM1: Trial 64 | BN1: Trial 65 | BO1: Trial 66 | BP1: Trial 67 | BQ1: Trial 68 | BR1: Trial 69 | BS1: Trial 70 | BT1: Trial 71 | BU1: Trial 72 | BV1: Trial 73 | BW1: Trial 74 | BX1: Trial 75 | BY1: Trial 76 | BZ1: Trial 77 | CA1: Trial 78 | CB1: Trial 79 | CC1: Trial 80 | CD1: Trial 81 | CE1: Trial 82 | CF1: Trial 83 | CG1: Trial 84 | CH1: Trial 85 | CI1: Trial 86 | CJ1: Trial 87 | CK1: Trial 88 | CL1: Trial 89 | CM1: Trial 90 | CN1: Trial 91 | CO1: Trial 92 | CP1: Trial 93 | CQ1: Trial 94 | CR1: Trial 95 | CS1: Trial 96 | CT1: Trial 97 | CU1: Trial 98 | CV1: Trial 99 | CW1: Trial 100 | CX1: Trial 101 | CY1: Trial 102 | CZ1: Trial 103 | DA1: Trial 104 | DB1: Trial 105 | DC1: Trial 106 | DD1: Trial 107 | DE1: Trial 108 | DF1: Trial 109 | DG1: Trial 110 | DH1: Trial 111 | DI1: Trial 112 | DJ1: Trial 113 | DK1: Trial 114 | DL1: Trial 115 | DM1: Trial 116 | DN1: Trial 117 | DO1: Trial 118 | DP1: Trial 119 | DQ1: Trial 120 | DR1: Trial 121 | DS1: Trial 122 | DT1: Trial 123 | DU1: Trial 124 | DV1: Trial 125 | DW1: Trial 126 | DX1: Trial 127 | DY1: Trial 128 | DZ1: Trial 129 | EA1: Trial 130 | EB1: Trial 131 | EC1: Trial 132 | ED1: Trial 133 | EE1: Trial 134 | EF1: Trial 135 | EG1: Trial 136 | EH1: Trial 137 | EI1: Trial 138 | EJ1: Trial 139 | EK1: Trial 140 | EL1: Trial 141 | EM1: Trial 142 | EN1: Trial 143 | EO1: Trial 144 | EP1: Trial 145 | EQ1: Trial 146 | ER1: Trial 147 | ES1: Trial 148 | ET1: Trial 149 | EU1: Trial 150 | EV1: Trial 151 | EW1: Trial 152 | EX1: Trial 153 | EY1: Trial 154 | EZ1: Trial 155 | FA1: Trial 156 | FB1: Trial 157 | FC1: Trial 158 | FD1: Trial 159 | FE1: Trial 160 | FF1: Trial 161 | FG1: Trial 162 | FH1: Trial 163 | FI1: Trial 164 | FJ1: Trial 165 | FK1: Trial 166 | FL1: Trial 167 | FM1: Trial 168 | FN1: Trial 169 | FO1: Trial 170 | FP1: Trial 171 | FQ1: Trial 172 | FR1: Trial 173 | FS1: Trial 174 | FT1: Trial 175 | FU1: Trial 176 | FV1: Trial 177 | FW1: Trial 178 | FX1: Trial 179 | FY1: Trial 180 | FZ1: Trial 181 | GA1: Trial 182 | GB1: Trial 183 | GC1: Trial 184 | GD1: Trial 185 | GE1: Trial 186 | GF1: Trial 187 | GG1: Trial 188 | GH1: Trial 189 | GI1: Trial 190 | GJ1: Trial 191 | GK1: Trial 192 | GL1: Trial 193 | GM1: Trial 194 | GN1: Trial 195 | GO1: Trial 196 | GP1: Trial 197 | GQ1: Trial 198 | GR1: Trial 199 | GS1: Trial 200 | GT1: Trial 201 | GU1: Trial 202 | GV1: Trial 203 | GW1: Trial 204 | GX1: Trial 205 | GY1: Trial 206 | GZ1: Trial 207 | HA1: Trial 208 | HB1: Trial 209 | HC1: Trial 210 | HD1: Trial 211 | HE1: Trial 212 | HF1: Trial 213 | HG1: Trial 214 | HH1: Trial 215 | HI1: Trial 216 | HJ1: Trial 217 | HK1: Trial 218 | HL1: Trial 219 | HM1: Trial 220 | HN1: Trial 221 | HO1: Trial 222 | HP1: Trial 223 | HQ1: Trial 224 | HR1: Trial 225 | HS1: Trial 226 | HT1: Trial 227 | HU1: Trial 228 | HV1: Trial 229 | HW1: Trial 230 | HX1: Trial 231 | HY1: Trial 232 | HZ1: Trial 233 | IA1: Trial 234 | IB1: Trial 235 | IC1: Trial 236 | ID1: Trial 237 | IE1: Trial 238 | IF1: Trial 239 | IG1: Trial 240 | IH1: Trial 241 | II1: Trial 242 | IJ1: Trial 243 | IK1: Trial 244 | IL1: Trial 245 | IM1: Trial 246 | IN1: Trial 247 | IO1: Trial 248 | IP1: Trial 249 | IQ1: Trial 250 | IR1: Trial 251 | IS1: Trial 252 | IT1: Trial 253 | IU1: Trial 254 | IV1: Trial 255 | IW1: Trial 256 | IX1: Trial 257 | IY1: Trial 258 | IZ1: Trial 259 | JA1: Trial 260 | JB1: Trial 261 | JC1: Trial 262 | JD1: Trial 263 | JE1: Trial 264 | JF1: Trial 265 | JG1: Trial 266 | JH1: Trial 267 | JI1: Trial 268 | JJ1: Trial 269 | JK1: Trial 270 | JL1: Trial 271 | JM1: Trial 272 | JN1: Trial 273 | JO1: Trial 274 | JP1: Trial 275 | JQ1: Trial 276 | JR1: Trial 277 | JS1: Trial 278 | JT1: Trial 279 | JU1: Trial 280 | JV1: Trial 281 | JW1: Trial 282 | JX1: Trial 283 | JY1: Trial 284 | JZ1: Trial 285 | KA1: Trial 286 | KB1: Trial 287 | KC1: Trial 288 | KD1: Trial 289 | KE1: Trial 290 | KF1: Trial 291 | KG1: Trial 292 | KH1: Trial 293 | KI1: Trial 294 | KJ1: Trial 295 | KK1: Trial 296 | KL1: Trial 297 | KM1: Trial 298 | KN1: Trial 299 | KO1: Trial 300 | KP1: Trial 301 | KQ1: Trial 302 | KR1: Trial 303 | KS1: Trial 304 | KT1: Trial 305 | KU1: Trial 306 | KV1: Trial 307 | KW1: Trial 308 | KX1: Trial 309 | KY1: Trial 310 | KZ1: Trial 311 | LA1: Trial 312 | LB1: Trial 313 | LC1: Trial 314 | LD1: Trial 315 | LE1: Trial 316 | LF1: Trial 317 | LG1: Trial 318 | LH1: Trial 319 | LI1: Trial 320 | LJ1: Trial 321 | LK1: Trial 322 | LL1: Trial 323 | LM1: Trial 324 | LN1: Trial 325 | LO1: Trial 326 | LP1: Trial 327 | LQ1: Trial 328 | LR1: Trial 329 | LS1: Trial 330 | LT1: Trial 331 | LU1: Trial 332 | LV1: Trial 333 | LW1: Trial 334 | LX1: Trial 335 | LY1: Trial 336 | LZ1: Trial 337 | MA1: Trial 338 | MB1: Trial 339 | MC1: Trial 340 | MD1: Trial 341 | ME1: Trial 342 | MF1: Trial 343 | MG1: Trial 344 | MH1: Trial 345 | MI1: Trial 346 | MJ1: Trial 347 | MK1: Trial 348 | ML1: Trial 349 | MM1: Trial 350 | MN1: Trial 351 | MO1: Trial 352 | MP1: Trial 353 | MQ1: Trial 354 | MR1: Trial 355 | MS1: Trial 356 | MT1: Trial 357 | MU1: Trial 358 | MV1: Trial 359 | MW1: Trial 360 | MX1: Trial 361 | MY1: Trial 362 | MZ1: Trial 363 | NA1: Trial 364 | NB1: Trial 365 | NC1: Trial 366 | ND1: Trial 367 | NE1: Trial 368 | NF1: Trial 369 | NG1: Trial 370 | NH1: Trial 371 | NI1: Trial 372 | NJ1: Trial 373 | NK1: Trial 374 | NL1: Trial 375 | NM1: Trial 376 | NN1: Trial 377 | NO1: Trial 378 | NP1: Trial 379 | NQ1: Trial 380 | NR1: Trial 381 | NS1: Trial 382 | NT1: Trial 383 | NU1: Trial 384 | NV1: Trial 385 | NW1: Trial 386 | NX1: Trial 387 | NY1: Trial 388 | NZ1: Trial 389 | OA1: Trial 390 | OB1: Trial 391 | OC1: Trial 392 | OD1: Trial 393 | OE1: Trial 394 | OF1: Trial 395 | OG1: Trial 396 | OH1: Trial 397 | OI1: Trial 398 | OJ1: Trial 399 | OK1: Trial 400 | OL1: Trial 401 | OM1: Trial 402 | ON1: Trial 403 | OO1: Trial 404 | OP1: Trial 405 | OQ1: Trial 406 | OR1: Trial 407 | OS1: Trial 408 | OT1: Trial 409 | OU1: Trial 410 | OV1: Trial 411 | OW1: Trial 412 | OX1: Trial 413 | OY1: Trial 414 | OZ1: Trial 415 | PA1: Trial 416 | PB1: Trial 417 | PC1: Trial 418 | PD1: Trial 419 | PE1: Trial 420 | PF1: Trial 421 | PG1: Trial 422 | PH1: Trial 423 | PI1: Trial 424 | PJ1: Trial 425 | PK1: Trial 426 | PL1: Trial 427 | PM1: Trial 428 | PN1: Trial 429 | PO1: Trial 430 | PP1: Trial 431 | PQ1: Trial 432 | PR1: Trial 433 | PS1: Trial 434 | PT1: Trial 435 | PU1: Trial 436 | PV1: Trial 437 | PW1: Trial 438 | PX1: Trial 439 | PY1: Trial 440 | PZ1: Trial 441 | QA1: Trial 442 | QB1: Trial 443 | QC1: Trial 444 | QD1: Trial 445 | QE1: Trial 446 | QF1: Trial 447 | QG1: Trial 448 | QH1: Trial 449 | QI1: Trial 450 | QJ1: Trial 451 | QK1: Trial 452 | QL1: Trial 453 | QM1: Trial 454 | QN1: Trial 455 | QO1: Trial 456 | QP1: Trial 457 | QQ1: Trial 458 | QR1: Trial 459 | QS1: Trial 460 | QT1: Trial 461 | QU1: Trial 462 | QV1: Trial 463 | QW1: Trial 464 | QX1: Trial 465 | QY1: Trial 466 | QZ1: Trial 467 | RA1: Trial 468 | RB1: Trial 469 | RC1: Trial 470 | RD1: Trial 471 | RE1: Trial 472 | RF1: Trial 473 | RG1: Trial 474 | RH1: Trial 475 | RI1: Trial 476 | RJ1: Trial 477 | RK1: Trial 478 | RL1: Trial 479 | RM1: Trial 480 | RN1: Trial 481 | RO1: Trial 482 | RP1: Trial 483 | RQ1: Trial 484 | RR1: Trial 485 | RS1: Trial 486 | RT1: Trial 487 | RU1: Trial 488 | RV1: Trial 489 | RW1: Trial 490 | RX1: Trial 491 | RY1: Trial 492 | RZ1: Trial 493 | SA1: Trial 494 | SB1: Trial 495 | SC1: Trial 496 | SD1: Trial 497 | SE1: Trial 498 | SF1: Trial 499 | SG1: Trial 500
A2: 債務者1 | B2: =IF(RAND()<Parameters!$B$4,1,0) | C2: =IF(RAND()<Parameters!$B$4,1,0) | D2: =IF(RAND()<Parameters!$B$4,1,0) | E2: =IF(RAND()<Parameters!$B$4,1,0) | F2: =IF(RAND()<Parameters!$B$4,1,0) | G2: =IF(RAND()<Parameters!$B$4,1,0) | H2: =IF(RAND()<Parameters!$B$4,1,0) | I2: =IF(RAND()<Parameters!$B$4,1,0) | ... SG2: =IF(RAND()<Parameters!$B$4,1,0)
A3: 債務者2 | B3: =IF(RAND()<Parameters!$B$4,1,0) | C3: =IF(RAND()<Parameters!$B$4,1,0) | D3: =IF(RAND()<Parameters!$B$4,1,0) | E3: =IF(RAND()<Parameters!$B$4,1,0) | F3: =IF(RAND()<Parameters!$B$4,1,0) | G3: =IF(RAND()<Parameters!$B$4,1,0) | H3: =IF(RAND()<Parameters!$B$4,1,0) | I3: =IF(RAND()<Parameters!$B$4,1,0) | ... SG3: =IF(RAND()<Parameters!$B$4,1,0)
A4: 債務者3 | B4: =IF(RAND()<Parameters!$B$4,1,0) | C4: =IF(RAND()<Parameters!$B$4,1,0) | D4: =IF(RAND()<Parameters!$B$4,1,0) | E4: =IF(RAND()<Parameters!$B$4,1,0) | F4: =IF(RAND()<Parameters!$B$4,1,0) | G4: =IF(RAND()<Parameters!$B$4,1,0) | H4: =IF(RAND()<Parameters!$B$4,1,0) | I4: =IF(RAND()<Parameters!$B$4,1,0) | ... SG4: =IF(RAND()<Parameters!$B$4,1,0)
A5: 債務者4 | B5: =IF(RAND()<Parameters!$B$4,1,0) | C5: =IF(RAND()<Parameters!$B$4,1,0) | D5: =IF(RAND()<Parameters!$B$4,1,0) | E5: =IF(RAND()<Parameters!$B$4,1,0) | F5: =IF(RAND()<Parameters!$B$4,1,0) | G5: =IF(RAND()<Parameters!$B$4,1,0) | H5: =IF(RAND()<Parameters!$B$4,1,0) | I5: =IF(RAND()<Parameters!$B$4,1,0) | ... SG5: =IF(RAND()<Parameters!$B$4,1,0)
A6: 債務者5 | B6: =IF(RAND()<Parameters!$B$4,1,0) | C6: =IF(RAND()<Parameters!$B$4,1,0) | D6: =IF(RAND()<Parameters!$B$4,1,0) | E6: =IF(RAND()<Parameters!$B$4,1,0) | F6: =IF(RAND()<Parameters!$B$4,1,0) | G6: =IF(RAND()<Parameters!$B$4,1,0) | H6: =IF(RAND()<Parameters!$B$4,1,0) | I6: =IF(RAND()<Parameters!$B$4,1,0) | ... SG6: =IF(RAND()<Parameters!$B$4,1,0)
A7: 債務者6 | B7: =IF(RAND()<Parameters!$B$4,1,0) | C7: =IF(RAND()<Parameters!$B$4,1,0) | D7: =IF(RAND()<Parameters!$B$4,1,0) | E7: =IF(RAND()<Parameters!$B$4,1,0) | F7: =IF(RAND()<Parameters!$B$4,1,0) | G7: =IF(RAND()<Parameters!$B$4,1,0) | H7: =IF(RAND()<Parameters!$B$4,1,0) | I7: =IF(RAND()<Parameters!$B$4,1,0) | ... SG7: =IF(RAND()<Parameters!$B$4,1,0)
A8: 債務者7 | B8: =IF(RAND()<Parameters!$B$4,1,0) | C8: =IF(RAND()<Parameters!$B$4,1,0) | D8: =IF(RAND()<Parameters!$B$4,1,0) | E8: =IF(RAND()<Parameters!$B$4,1,0) | F8: =IF(RAND()<Parameters!$B$4,1,0) | G8: =IF(RAND()<Parameters!$B$4,1,0) | H8: =IF(RAND()<Parameters!$B$4,1,0) | I8: =IF(RAND()<Parameters!$B$4,1,0) | ... SG8: =IF(RAND()<Parameters!$B$4,1,0)
A9: 債務者8 | B9: =IF(RAND()<Parameters!$B$4,1,0) | C9: =IF(RAND()<Parameters!$B$4,1,0) | D9: =IF(RAND()<Parameters!$B$4,1,0) | E9: =IF(RAND()<Parameters!$B$4,1,0) | F9: =IF(RAND()<Parameters!$B$4,1,0) | G9: =IF(RAND()<Parameters!$B$4,1,0) | H9: =IF(RAND()<Parameters!$B$4,1,0) | I9: =IF(RAND()<Parameters!$B$4,1,0) | ... SG9: =IF(RAND()<Parameters!$B$4,1,0)
A10: 債務者9 | B10: =IF(RAND()<Parameters!$B$4,1,0) | C10: =IF(RAND()<Parameters!$B$4,1,0) | D10: =IF(RAND()<Parameters!$B$4,1,0) | E10: =IF(RAND()<Parameters!$B$4,1,0) | F10: =IF(RAND()<Parameters!$B$4,1,0) | G10: =IF(RAND()<Parameters!$B$4,1,0) | H10: =IF(RAND()<Parameters!$B$4,1,0) | I10: =IF(RAND()<Parameters!$B$4,1,0) | ... SG10: =IF(RAND()<Parameters!$B$4,1,0)
A11: 債務者10 | B11: =IF(RAND()<Parameters!$B$4,1,0) | C11: =IF(RAND()<Parameters!$B$4,1,0) | D11: =IF(RAND()<Parameters!$B$4,1,0) | E11: =IF(RAND()<Parameters!$B$4,1,0) | F11: =IF(RAND()<Parameters!$B$4,1,0) | G11: =IF(RAND()<Parameters!$B$4,1,0) | H11: =IF(RAND()<Parameters!$B$4,1,0) | I11: =IF(RAND()<Parameters!$B$4,1,0) | ... SG11: =IF(RAND()<Parameters!$B$4,1,0)
A13: Portfolio Loss | B13: =SUMPRODUCT(B2:B11,Weights!B$5:K$5)*Parameters!$B$5 | C13: =SUMPRODUCT(C2:C11,Weights!B$5:K$5)*Parameters!$B$5 | D13: =SUMPRODUCT(D2:D11,Weights!B$5:K$5)*Parameters!$B$5 | E13: =SUMPRODUCT(E2:E11,Weights!B$5:K$5)*Parameters!$B$5 | F13: =SUMPRODUCT(F2:F11,Weights!B$5:K$5)*Parameters!$B$5 | G13: =SUMPRODUCT(G2:G11,Weights!B$5:K$5)*Parameters!$B$5 | H13: =SUMPRODUCT(H2:H11,Weights!B$5:K$5)*Parameters!$B$5 | I13: =SUMPRODUCT(I2:I11,Weights!B$5:K$5)*Parameters!$B$5 | J13: =SUMPRODUCT(J2:J11,Weights!B$5:K$5)*Parameters!$B$5 | K13: =SUMPRODUCT(K2:K11,Weights!B$5:K$5)*Parameters!$B$5 | L13: =SUMPRODUCT(L2:L11,Weights!B$5:K$5)*Parameters!$B$5 | M13: =SUMPRODUCT(M2:M11,Weights!B$5:K$5)*Parameters!$B$5 | N13: =SUMPRODUCT(N2:N11,Weights!B$5:K$5)*Parameters!$B$5 | O13: =SUMPRODUCT(O2:O11,Weights!B$5:K$5)*Parameters!$B$5 | P13: =SUMPRODUCT(P2:P11,Weights!B$5:K$5)*Parameters!$B$5 | Q13: =SUMPRODUCT(Q2:Q11,Weights!B$5:K$5)*Parameters!$B$5 | R13: =SUMPRODUCT(R2:R11,Weights!B$5:K$5)*Parameters!$B$5 | S13: =SUMPRODUCT(S2:S11,Weights!B$5:K$5)*Parameters!$B$5 | T13: =SUMPRODUCT(T2:T11,Weights!B$5:K$5)*Parameters!$B$5 | U13: =SUMPRODUCT(U2:U11,Weights!B$5:K$5)*Parameters!$B$5 | V13: =SUMPRODUCT(V2:V11,Weights!B$5:K$5)*Parameters!$B$5 | W13: =SUMPRODUCT(W2:W11,Weights!B$5:K$5)*Parameters!$B$5 | X13: =SUMPRODUCT(X2:X11,Weights!B$5:K$5)*Parameters!$B$5 | Y13: =SUMPRODUCT(Y2:Y11,Weights!B$5:K$5)*Parameters!$B$5 | Z13: =SUMPRODUCT(Z2:Z11,Weights!B$5:K$5)*Parameters!$B$5 | AA13: =SUMPRODUCT(AA2:AA11,Weights!B$5:K$5)*Parameters!$B$5 | AB13: =SUMPRODUCT(AB2:AB11,Weights!B$5:K$5)*Parameters!$B$5 | AC13: =SUMPRODUCT(AC2:AC11,Weights!B$5:K$5)*Parameters!$B$5 | AD13: =SUMPRODUCT(AD2:AD11,Weights!B$5:K$5)*Parameters!$B$5 | AE13: =SUMPRODUCT(AE2:AE11,Weights!B$5:K$5)*Parameters!$B$5 | AF13: =SUMPRODUCT(AF2:AF11,Weights!B$5:K$5)*Parameters!$B$5 | AG13: =SUMPRODUCT(AG2:AG11,Weights!B$5:K$5)*Parameters!$B$5 | AH13: =SUMPRODUCT(AH2:AH11,Weights!B$5:K$5)*Parameters!$B$5 | AI13: =SUMPRODUCT(AI2:AI11,Weights!B$5:K$5)*Parameters!$B$5 | AJ13: =SUMPRODUCT(AJ2:AJ11,Weights!B$5:K$5)*Parameters!$B$5 | AK13: =SUMPRODUCT(AK2:AK11,Weights!B$5:K$5)*Parameters!$B$5 | AL13: =SUMPRODUCT(AL2:AL11,Weights!B$5:K$5)*Parameters!$B$5 | AM13: =SUMPRODUCT(AM2:AM11,Weights!B$5:K$5)*Parameters!$B$5 | AN13: =SUMPRODUCT(AN2:AN11,Weights!B$5:K$5)*Parameters!$B$5 | AO13: =SUMPRODUCT(AO2:AO11,Weights!B$5:K$5)*Parameters!$B$5 | AP13: =SUMPRODUCT(AP2:AP11,Weights!B$5:K$5)*Parameters!$B$5 | AQ13: =SUMPRODUCT(AQ2:AQ11,Weights!B$5:K$5)*Parameters!$B$5 | AR13: =SUMPRODUCT(AR2:AR11,Weights!B$5:K$5)*Parameters!$B$5 | AS13: =SUMPRODUCT(AS2:AS11,Weights!B$5:K$5)*Parameters!$B$5 | AT13: =SUMPRODUCT(AT2:AT11,Weights!B$5:K$5)*Parameters!$B$5 | AU13: =SUMPRODUCT(AU2:AU11,Weights!B$5:K$5)*Parameters!$B$5 | AV13: =SUMPRODUCT(AV2:AV11,Weights!B$5:K$5)*Parameters!$B$5 | AW13: =SUMPRODUCT(AW2:AW11,Weights!B$5:K$5)*Parameters!$B$5 | AX13: =SUMPRODUCT(AX2:AX11,Weights!B$5:K$5)*Parameters!$B$5 | AY13: =SUMPRODUCT(AY2:AY11,Weights!B$5:K$5)*Parameters!$B$5 | AZ13: =SUMPRODUCT(AZ2:AZ11,Weights!B$5:K$5)*Parameters!$B$5 | BA13: =SUMPRODUCT(BA2:BA11,Weights!B$5:K$5)*Parameters!$B$5 | BB13: =SUMPRODUCT(BB2:BB11,Weights!B$5:K$5)*Parameters!$B$5 | BC13: =SUMPRODUCT(BC2:BC11,Weights!B$5:K$5)*Parameters!$B$5 | BD13: =SUMPRODUCT(BD2:BD11,Weights!B$5:K$5)*Parameters!$B$5 | BE13: =SUMPRODUCT(BE2:BE11,Weights!B$5:K$5)*Parameters!$B$5 | BF13: =SUMPRODUCT(BF2:BF11,Weights!B$5:K$5)*Parameters!$B$5 | BG13: =SUMPRODUCT(BG2:BG11,Weights!B$5:K$5)*Parameters!$B$5 | BH13: =SUMPRODUCT(BH2:BH11,Weights!B$5:K$5)*Parameters!$B$5 | BI13: =SUMPRODUCT(BI2:BI11,Weights!B$5:K$5)*Parameters!$B$5 | BJ13: =SUMPRODUCT(BJ2:BJ11,Weights!B$5:K$5)*Parameters!$B$5 | BK13: =SUMPRODUCT(BK2:BK11,Weights!B$5:K$5)*Parameters!$B$5 | BL13: =SUMPRODUCT(BL2:BL11,Weights!B$5:K$5)*Parameters!$B$5 | BM13: =SUMPRODUCT(BM2:BM11,Weights!B$5:K$5)*Parameters!$B$5 | BN13: =SUMPRODUCT(BN2:BN11,Weights!B$5:K$5)*Parameters!$B$5 | BO13: =SUMPRODUCT(BO2:BO11,Weights!B$5:K$5)*Parameters!$B$5 | BP13: =SUMPRODUCT(BP2:BP11,Weights!B$5:K$5)*Parameters!$B$5 | BQ13: =SUMPRODUCT(BQ2:BQ11,Weights!B$5:K$5)*Parameters!$B$5 | BR13: =SUMPRODUCT(BR2:BR11,Weights!B$5:K$5)*Parameters!$B$5 | BS13: =SUMPRODUCT(BS2:BS11,Weights!B$5:K$5)*Parameters!$B$5 | BT13: =SUMPRODUCT(BT2:BT11,Weights!B$5:K$5)*Parameters!$B$5 | BU13: =SUMPRODUCT(BU2:BU11,Weights!B$5:K$5)*Parameters!$B$5 | BV13: =SUMPRODUCT(BV2:BV11,Weights!B$5:K$5)*Parameters!$B$5 | BW13: =SUMPRODUCT(BW2:BW11,Weights!B$5:K$5)*Parameters!$B$5 | BX13: =SUMPRODUCT(BX2:BX11,Weights!B$5:K$5)*Parameters!$B$5 | BY13: =SUMPRODUCT(BY2:BY11,Weights!B$5:K$5)*Parameters!$B$5 | BZ13: =SUMPRODUCT(BZ2:BZ11,Weights!B$5:K$5)*Parameters!$B$5 | CA13: =SUMPRODUCT(CA2:CA11,Weights!B$5:K$5)*Parameters!$B$5 | CB13: =SUMPRODUCT(CB2:CB11,Weights!B$5:K$5)*Parameters!$B$5 | CC13: =SUMPRODUCT(CC2:CC11,Weights!B$5:K$5)*Parameters!$B$5 | CD13: =SUMPRODUCT(CD2:CD11,Weights!B$5:K$5)*Parameters!$B$5 | CE13: =SUMPRODUCT(CE2:CE11,Weights!B$5:K$5)*Parameters!$B$5 | CF13: =SUMPRODUCT(CF2:CF11,Weights!B$5:K$5)*Parameters!$B$5 | CG13: =SUMPRODUCT(CG2:CG11,Weights!B$5:K$5)*Parameters!$B$5 | CH13: =SUMPRODUCT(CH2:CH11,Weights!B$5:K$5)*Parameters!$B$5 | CI13: =SUMPRODUCT(CI2:CI11,Weights!B$5:K$5)*Parameters!$B$5 | CJ13: =SUMPRODUCT(CJ2:CJ11,Weights!B$5:K$5)*Parameters!$B$5 | CK13: =SUMPRODUCT(CK2:CK11,Weights!B$5:K$5)*Parameters!$B$5 | CL13: =SUMPRODUCT(CL2:CL11,Weights!B$5:K$5)*Parameters!$B$5 | CM13: =SUMPRODUCT(CM2:CM11,Weights!B$5:K$5)*Parameters!$B$5 | CN13: =SUMPRODUCT(CN2:CN11,Weights!B$5:K$5)*Parameters!$B$5 | CO13: =SUMPRODUCT(CO2:CO11,Weights!B$5:K$5)*Parameters!$B$5 | CP13: =SUMPRODUCT(CP2:CP11,Weights!B$5:K$5)*Parameters!$B$5 | CQ13: =SUMPRODUCT(CQ2:CQ11,Weights!B$5:K$5)*Parameters!$B$5 | CR13: =SUMPRODUCT(CR2:CR11,Weights!B$5:K$5)*Parameters!$B$5 | CS13: =SUMPRODUCT(CS2:CS11,Weights!B$5:K$5)*Parameters!$B$5 | CT13: =SUMPRODUCT(CT2:CT11,Weights!B$5:K$5)*Parameters!$B$5 | CU13: =SUMPRODUCT(CU2:CU11,Weights!B$5:K$5)*Parameters!$B$5 | CV13: =SUMPRODUCT(CV2:CV11,Weights!B$5:K$5)*Parameters!$B$5 | CW13: =SUMPRODUCT(CW2:CW11,Weights!B$5:K$5)*Parameters!$B$5 | CX13: =SUMPRODUCT(CX2:CX11,Weights!B$5:K$5)*Parameters!$B$5 | CY13: =SUMPRODUCT(CY2:CY11,Weights!B$5:K$5)*Parameters!$B$5 | CZ13: =SUMPRODUCT(CZ2:CZ11,Weights!B$5:K$5)*Parameters!$B$5 | DA13: =SUMPRODUCT(DA2:DA11,Weights!B$5:K$5)*Parameters!$B$5 | DB13: =SUMPRODUCT(DB2:DB11,Weights!B$5:K$5)*Parameters!$B$5 | DC13: =SUMPRODUCT(DC2:DC11,Weights!B$5:K$5)*Parameters!$B$5 | DD13: =SUMPRODUCT(DD2:DD11,Weights!B$5:K$5)*Parameters!$B$5 | DE13: =SUMPRODUCT(DE2:DE11,Weights!B$5:K$5)*Parameters!$B$5 | DF13: =SUMPRODUCT(DF2:DF11,Weights!B$5:K$5)*Parameters!$B$5 | DG13: =SUMPRODUCT(DG2:DG11,Weights!B$5:K$5)*Parameters!$B$5 | DH13: =SUMPRODUCT(DH2:DH11,Weights!B$5:K$5)*Parameters!$B$5 | DI13: =SUMPRODUCT(DI2:DI11,Weights!B$5:K$5)*Parameters!$B$5 | DJ13: =SUMPRODUCT(DJ2:DJ11,Weights!B$5:K$5)*Parameters!$B$5 | DK13: =SUMPRODUCT(DK2:DK11,Weights!B$5:K$5)*Parameters!$B$5 | DL13: =SUMPRODUCT(DL2:DL11,Weights!B$5:K$5)*Parameters!$B$5 | DM13: =SUMPRODUCT(DM2:DM11,Weights!B$5:K$5)*Parameters!$B$5 | DN13: =SUMPRODUCT(DN2:DN11,Weights!B$5:K$5)*Parameters!$B$5 | DO13: =SUMPRODUCT(DO2:DO11,Weights!B$5:K$5)*Parameters!$B$5 | DP13: =SUMPRODUCT(DP2:DP11,Weights!B$5:K$5)*Parameters!$B$5 | DQ13: =SUMPRODUCT(DQ2:DQ11,Weights!B$5:K$5)*Parameters!$B$5 | DR13: =SUMPRODUCT(DR2:DR11,Weights!B$5:K$5)*Parameters!$B$5 | DS13: =SUMPRODUCT(DS2:DS11,Weights!B$5:K$5)*Parameters!$B$5 | DT13: =SUMPRODUCT(DT2:DT11,Weights!B$5:K$5)*Parameters!$B$5 | DU13: =SUMPRODUCT(DU2:DU11,Weights!B$5:K$5)*Parameters!$B$5 | DV13: =SUMPRODUCT(DV2:DV11,Weights!B$5:K$5)*Parameters!$B$5 | DW13: =SUMPRODUCT(DW2:DW11,Weights!B$5:K$5)*Parameters!$B$5 | DX13: =SUMPRODUCT(DX2:DX11,Weights!B$5:K$5)*Parameters!$B$5 | DY13: =SUMPRODUCT(DY2:DY11,Weights!B$5:K$5)*Parameters!$B$5 | DZ13: =SUMPRODUCT(DZ2:DZ11,Weights!B$5:K$5)*Parameters!$B$5 | EA13: =SUMPRODUCT(EA2:EA11,Weights!B$5:K$5)*Parameters!$B$5 | EB13: =SUMPRODUCT(EB2:EB11,Weights!B$5:K$5)*Parameters!$B$5 | EC13: =SUMPRODUCT(EC2:EC11,Weights!B$5:K$5)*Parameters!$B$5 | ED13: =SUMPRODUCT(ED2:ED11,Weights!B$5:K$5)*Parameters!$B$5 | EE13: =SUMPRODUCT(EE2:EE11,Weights!B$5:K$5)*Parameters!$B$5 | EF13: =SUMPRODUCT(EF2:EF11,Weights!B$5:K$5)*Parameters!$B$5 | EG13: =SUMPRODUCT(EG2:EG11,Weights!B$5:K$5)*Parameters!$B$5 | EH13: =SUMPRODUCT(EH2:EH11,Weights!B$5:K$5)*Parameters!$B$5 | EI13: =SUMPRODUCT(EI2:EI11,Weights!B$5:K$5)*Parameters!$B$5 | EJ13: =SUMPRODUCT(EJ2:EJ11,Weights!B$5:K$5)*Parameters!$B$5 | EK13: =SUMPRODUCT(EK2:EK11,Weights!B$5:K$5)*Parameters!$B$5 | EL13: =SUMPRODUCT(EL2:EL11,Weights!B$5:K$5)*Parameters!$B$5 | EM13: =SUMPRODUCT(EM2:EM11,Weights!B$5:K$5)*Parameters!$B$5 | EN13: =SUMPRODUCT(EN2:EN11,Weights!B$5:K$5)*Parameters!$B$5 | EO13: =SUMPRODUCT(EO2:EO11,Weights!B$5:K$5)*Parameters!$B$5 | EP13: =SUMPRODUCT(EP2:EP11,Weights!B$5:K$5)*Parameters!$B$5 | EQ13: =SUMPRODUCT(EQ2:EQ11,Weights!B$5:K$5)*Parameters!$B$5 | ER13: =SUMPRODUCT(ER2:ER11,Weights!B$5:K$5)*Parameters!$B$5 | ES13: =SUMPRODUCT(ES2:ES11,Weights!B$5:K$5)*Parameters!$B$5 | ET13: =SUMPRODUCT(ET2:ET11,Weights!B$5:K$5)*Parameters!$B$5 | EU13: =SUMPRODUCT(EU2:EU11,Weights!B$5:K$5)*Parameters!$B$5 | EV13: =SUMPRODUCT(EV2:EV11,Weights!B$5:K$5)*Parameters!$B$5 | EW13: =SUMPRODUCT(EW2:EW11,Weights!B$5:K$5)*Parameters!$B$5 | EX13: =SUMPRODUCT(EX2:EX11,Weights!B$5:K$5)*Parameters!$B$5 | EY13: =SUMPRODUCT(EY2:EY11,Weights!B$5:K$5)*Parameters!$B$5 | EZ13: =SUMPRODUCT(EZ2:EZ11,Weights!B$5:K$5)*Parameters!$B$5 | FA13: =SUMPRODUCT(FA2:FA11,Weights!B$5:K$5)*Parameters!$B$5 | FB13: =SUMPRODUCT(FB2:FB11,Weights!B$5:K$5)*Parameters!$B$5 | FC13: =SUMPRODUCT(FC2:FC11,Weights!B$5:K$5)*Parameters!$B$5 | FD13: =SUMPRODUCT(FD2:FD11,Weights!B$5:K$5)*Parameters!$B$5 | FE13: =SUMPRODUCT(FE2:FE11,Weights!B$5:K$5)*Parameters!$B$5 | FF13: =SUMPRODUCT(FF2:FF11,Weights!B$5:K$5)*Parameters!$B$5 | FG13: =SUMPRODUCT(FG2:FG11,Weights!B$5:K$5)*Parameters!$B$5 | FH13: =SUMPRODUCT(FH2:FH11,Weights!B$5:K$5)*Parameters!$B$5 | FI13: =SUMPRODUCT(FI2:FI11,Weights!B$5:K$5)*Parameters!$B$5 | FJ13: =SUMPRODUCT(FJ2:FJ11,Weights!B$5:K$5)*Parameters!$B$5 | FK13: =SUMPRODUCT(FK2:FK11,Weights!B$5:K$5)*Parameters!$B$5 | FL13: =SUMPRODUCT(FL2:FL11,Weights!B$5:K$5)*Parameters!$B$5 | FM13: =SUMPRODUCT(FM2:FM11,Weights!B$5:K$5)*Parameters!$B$5 | FN13: =SUMPRODUCT(FN2:FN11,Weights!B$5:K$5)*Parameters!$B$5 | FO13: =SUMPRODUCT(FO2:FO11,Weights!B$5:K$5)*Parameters!$B$5 | FP13: =SUMPRODUCT(FP2:FP11,Weights!B$5:K$5)*Parameters!$B$5 | FQ13: =SUMPRODUCT(FQ2:FQ11,Weights!B$5:K$5)*Parameters!$B$5 | FR13: =SUMPRODUCT(FR2:FR11,Weights!B$5:K$5)*Parameters!$B$5 | FS13: =SUMPRODUCT(FS2:FS11,Weights!B$5:K$5)*Parameters!$B$5 | FT13: =SUMPRODUCT(FT2:FT11,Weights!B$5:K$5)*Parameters!$B$5 | FU13: =SUMPRODUCT(FU2:FU11,Weights!B$5:K$5)*Parameters!$B$5 | FV13: =SUMPRODUCT(FV2:FV11,Weights!B$5:K$5)*Parameters!$B$5 | FW13: =SUMPRODUCT(FW2:FW11,Weights!B$5:K$5)*Parameters!$B$5 | FX13: =SUMPRODUCT(FX2:FX11,Weights!B$5:K$5)*Parameters!$B$5 | FY13: =SUMPRODUCT(FY2:FY11,Weights!B$5:K$5)*Parameters!$B$5 | FZ13: =SUMPRODUCT(FZ2:FZ11,Weights!B$5:K$5)*Parameters!$B$5 | GA13: =SUMPRODUCT(GA2:GA11,Weights!B$5:K$5)*Parameters!$B$5 | GB13: =SUMPRODUCT(GB2:GB11,Weights!B$5:K$5)*Parameters!$B$5 | GC13: =SUMPRODUCT(GC2:GC11,Weights!B$5:K$5)*Parameters!$B$5 | GD13: =SUMPRODUCT(GD2:GD11,Weights!B$5:K$5)*Parameters!$B$5 | GE13: =SUMPRODUCT(GE2:GE11,Weights!B$5:K$5)*Parameters!$B$5 | GF13: =SUMPRODUCT(GF2:GF11,Weights!B$5:K$5)*Parameters!$B$5 | GG13: =SUMPRODUCT(GG2:GG11,Weights!B$5:K$5)*Parameters!$B$5 | GH13: =SUMPRODUCT(GH2:GH11,Weights!B$5:K$5)*Parameters!$B$5 | GI13: =SUMPRODUCT(GI2:GI11,Weights!B$5:K$5)*Parameters!$B$5 | GJ13: =SUMPRODUCT(GJ2:GJ11,Weights!B$5:K$5)*Parameters!$B$5 | GK13: =SUMPRODUCT(GK2:GK11,Weights!B$5:K$5)*Parameters!$B$5 | GL13: =SUMPRODUCT(GL2:GL11,Weights!B$5:K$5)*Parameters!$B$5 | GM13: =SUMPRODUCT(GM2:GM11,Weights!B$5:K$5)*Parameters!$B$5 | GN13: =SUMPRODUCT(GN2:GN11,Weights!B$5:K$5)*Parameters!$B$5 | GO13: =SUMPRODUCT(GO2:GO11,Weights!B$5:K$5)*Parameters!$B$5 | GP13: =SUMPRODUCT(GP2:GP11,Weights!B$5:K$5)*Parameters!$B$5 | GQ13: =SUMPRODUCT(GQ2:GQ11,Weights!B$5:K$5)*Parameters!$B$5 | GR13: =SUMPRODUCT(GR2:GR11,Weights!B$5:K$5)*Parameters!$B$5 | GS13: =SUMPRODUCT(GS2:GS11,Weights!B$5:K$5)*Parameters!$B$5 | GT13: =SUMPRODUCT(GT2:GT11,Weights!B$5:K$5)*Parameters!$B$5 | GU13: =SUMPRODUCT(GU2:GU11,Weights!B$5:K$5)*Parameters!$B$5 | GV13: =SUMPRODUCT(GV2:GV11,Weights!B$5:K$5)*Parameters!$B$5 | GW13: =SUMPRODUCT(GW2:GW11,Weights!B$5:K$5)*Parameters!$B$5 | GX13: =SUMPRODUCT(GX2:GX11,Weights!B$5:K$5)*Parameters!$B$5 | GY13: =SUMPRODUCT(GY2:GY11,Weights!B$5:K$5)*Parameters!$B$5 | GZ13: =SUMPRODUCT(GZ2:GZ11,Weights!B$5:K$5)*Parameters!$B$5 | HA13: =SUMPRODUCT(HA2:HA11,Weights!B$5:K$5)*Parameters!$B$5 | HB13: =SUMPRODUCT(HB2:HB11,Weights!B$5:K$5)*Parameters!$B$5 | HC13: =SUMPRODUCT(HC2:HC11,Weights!B$5:K$5)*Parameters!$B$5 | HD13: =SUMPRODUCT(HD2:HD11,Weights!B$5:K$5)*Parameters!$B$5 | HE13: =SUMPRODUCT(HE2:HE11,Weights!B$5:K$5)*Parameters!$B$5 | HF13: =SUMPRODUCT(HF2:HF11,Weights!B$5:K$5)*Parameters!$B$5 | HG13: =SUMPRODUCT(HG2:HG11,Weights!B$5:K$5)*Parameters!$B$5 | HH13: =SUMPRODUCT(HH2:HH11,Weights!B$5:K$5)*Parameters!$B$5 | HI13: =SUMPRODUCT(HI2:HI11,Weights!B$5:K$5)*Parameters!$B$5 | HJ13: =SUMPRODUCT(HJ2:HJ11,Weights!B$5:K$5)*Parameters!$B$5 | HK13: =SUMPRODUCT(HK2:HK11,Weights!B$5:K$5)*Parameters!$B$5 | HL13: =SUMPRODUCT(HL2:HL11,Weights!B$5:K$5)*Parameters!$B$5 | HM13: =SUMPRODUCT(HM2:HM11,Weights!B$5:K$5)*Parameters!$B$5 | HN13: =SUMPRODUCT(HN2:HN11,Weights!B$5:K$5)*Parameters!$B$5 | HO13: =SUMPRODUCT(HO2:HO11,Weights!B$5:K$5)*Parameters!$B$5 | HP13: =SUMPRODUCT(HP2:HP11,Weights!B$5:K$5)*Parameters!$B$5 | HQ13: =SUMPRODUCT(HQ2:HQ11,Weights!B$5:K$5)*Parameters!$B$5 | HR13: =SUMPRODUCT(HR2:HR11,Weights!B$5:K$5)*Parameters!$B$5 | HS13: =SUMPRODUCT(HS2:HS11,Weights!B$5:K$5)*Parameters!$B$5 | HT13: =SUMPRODUCT(HT2:HT11,Weights!B$5:K$5)*Parameters!$B$5 | HU13: =SUMPRODUCT(HU2:HU11,Weights!B$5:K$5)*Parameters!$B$5 | HV13: =SUMPRODUCT(HV2:HV11,Weights!B$5:K$5)*Parameters!$B$5 | HW13: =SUMPRODUCT(HW2:HW11,Weights!B$5:K$5)*Parameters!$B$5 | HX13: =SUMPRODUCT(HX2:HX11,Weights!B$5:K$5)*Parameters!$B$5 | HY13: =SUMPRODUCT(HY2:HY11,Weights!B$5:K$5)*Parameters!$B$5 | HZ13: =SUMPRODUCT(HZ2:HZ11,Weights!B$5:K$5)*Parameters!$B$5 | IA13: =SUMPRODUCT(IA2:IA11,Weights!B$5:K$5)*Parameters!$B$5 | IB13: =SUMPRODUCT(IB2:IB11,Weights!B$5:K$5)*Parameters!$B$5 | IC13: =SUMPRODUCT(IC2:IC11,Weights!B$5:K$5)*Parameters!$B$5 | ID13: =SUMPRODUCT(ID2:ID11,Weights!B$5:K$5)*Parameters!$B$5 | IE13: =SUMPRODUCT(IE2:IE11,Weights!B$5:K$5)*Parameters!$B$5 | IF13: =SUMPRODUCT(IF2:IF11,Weights!B$5:K$5)*Parameters!$B$5 | IG13: =SUMPRODUCT(IG2:IG11,Weights!B$5:K$5)*Parameters!$B$5 | IH13: =SUMPRODUCT(IH2:IH11,Weights!B$5:K$5)*Parameters!$B$5 | II13: =SUMPRODUCT(II2:II11,Weights!B$5:K$5)*Parameters!$B$5 | IJ13: =SUMPRODUCT(IJ2:IJ11,Weights!B$5:K$5)*Parameters!$B$5 | IK13: =SUMPRODUCT(IK2:IK11,Weights!B$5:K$5)*Parameters!$B$5 | IL13: =SUMPRODUCT(IL2:IL11,Weights!B$5:K$5)*Parameters!$B$5 | IM13: =SUMPRODUCT(IM2:IM11,Weights!B$5:K$5)*Parameters!$B$5 | IN13: =SUMPRODUCT(IN2:IN11,Weights!B$5:K$5)*Parameters!$B$5 | IO13: =SUMPRODUCT(IO2:IO11,Weights!B$5:K$5)*Parameters!$B$5 | IP13: =SUMPRODUCT(IP2:IP11,Weights!B$5:K$5)*Parameters!$B$5 | IQ13: =SUMPRODUCT(IQ2:IQ11,Weights!B$5:K$5)*Parameters!$B$5 | IR13: =SUMPRODUCT(IR2:IR11,Weights!B$5:K$5)*Parameters!$B$5 | IS13: =SUMPRODUCT(IS2:IS11,Weights!B$5:K$5)*Parameters!$B$5 | IT13: =SUMPRODUCT(IT2:IT11,Weights!B$5:K$5)*Parameters!$B$5 | IU13: =SUMPRODUCT(IU2:IU11,Weights!B$5:K$5)*Parameters!$B$5 | IV13: =SUMPRODUCT(IV2:IV11,Weights!B$5:K$5)*Parameters!$B$5 | IW13: =SUMPRODUCT(IW2:IW11,Weights!B$5:K$5)*Parameters!$B$5 | IX13: =SUMPRODUCT(IX2:IX11,Weights!B$5:K$5)*Parameters!$B$5 | IY13: =SUMPRODUCT(IY2:IY11,Weights!B$5:K$5)*Parameters!$B$5 | IZ13: =SUMPRODUCT(IZ2:IZ11,Weights!B$5:K$5)*Parameters!$B$5 | JA13: =SUMPRODUCT(JA2:JA11,Weights!B$5:K$5)*Parameters!$B$5 | JB13: =SUMPRODUCT(JB2:JB11,Weights!B$5:K$5)*Parameters!$B$5 | JC13: =SUMPRODUCT(JC2:JC11,Weights!B$5:K$5)*Parameters!$B$5 | JD13: =SUMPRODUCT(JD2:JD11,Weights!B$5:K$5)*Parameters!$B$5 | JE13: =SUMPRODUCT(JE2:JE11,Weights!B$5:K$5)*Parameters!$B$5 | JF13: =SUMPRODUCT(JF2:JF11,Weights!B$5:K$5)*Parameters!$B$5 | JG13: =SUMPRODUCT(JG2:JG11,Weights!B$5:K$5)*Parameters!$B$5 | JH13: =SUMPRODUCT(JH2:JH11,Weights!B$5:K$5)*Parameters!$B$5 | JI13: =SUMPRODUCT(JI2:JI11,Weights!B$5:K$5)*Parameters!$B$5 | JJ13: =SUMPRODUCT(JJ2:JJ11,Weights!B$5:K$5)*Parameters!$B$5 | JK13: =SUMPRODUCT(JK2:JK11,Weights!B$5:K$5)*Parameters!$B$5 | JL13: =SUMPRODUCT(JL2:JL11,Weights!B$5:K$5)*Parameters!$B$5 | JM13: =SUMPRODUCT(JM2:JM11,Weights!B$5:K$5)*Parameters!$B$5 | JN13: =SUMPRODUCT(JN2:JN11,Weights!B$5:K$5)*Parameters!$B$5 | JO13: =SUMPRODUCT(JO2:JO11,Weights!B$5:K$5)*Parameters!$B$5 | JP13: =SUMPRODUCT(JP2:JP11,Weights!B$5:K$5)*Parameters!$B$5 | JQ13: =SUMPRODUCT(JQ2:JQ11,Weights!B$5:K$5)*Parameters!$B$5 | JR13: =SUMPRODUCT(JR2:JR11,Weights!B$5:K$5)*Parameters!$B$5 | JS13: =SUMPRODUCT(JS2:JS11,Weights!B$5:K$5)*Parameters!$B$5 | JT13: =SUMPRODUCT(JT2:JT11,Weights!B$5:K$5)*Parameters!$B$5 | JU13: =SUMPRODUCT(JU2:JU11,Weights!B$5:K$5)*Parameters!$B$5 | JV13: =SUMPRODUCT(JV2:JV11,Weights!B$5:K$5)*Parameters!$B$5 | JW13: =SUMPRODUCT(JW2:JW11,Weights!B$5:K$5)*Parameters!$B$5 | JX13: =SUMPRODUCT(JX2:JX11,Weights!B$5:K$5)*Parameters!$B$5 | JY13: =SUMPRODUCT(JY2:JY11,Weights!B$5:K$5)*Parameters!$B$5 | JZ13: =SUMPRODUCT(JZ2:JZ11,Weights!B$5:K$5)*Parameters!$B$5 | KA13: =SUMPRODUCT(KA2:KA11,Weights!B$5:K$5)*Parameters!$B$5 | KB13: =SUMPRODUCT(KB2:KB11,Weights!B$5:K$5)*Parameters!$B$5 | KC13: =SUMPRODUCT(KC2:KC11,Weights!B$5:K$5)*Parameters!$B$5 | KD13: =SUMPRODUCT(KD2:KD11,Weights!B$5:K$5)*Parameters!$B$5 | KE13: =SUMPRODUCT(KE2:KE11,Weights!B$5:K$5)*Parameters!$B$5 | KF13: =SUMPRODUCT(KF2:KF11,Weights!B$5:K$5)*Parameters!$B$5 | KG13: =SUMPRODUCT(KG2:KG11,Weights!B$5:K$5)*Parameters!$B$5 | KH13: =SUMPRODUCT(KH2:KH11,Weights!B$5:K$5)*Parameters!$B$5 | KI13: =SUMPRODUCT(KI2:KI11,Weights!B$5:K$5)*Parameters!$B$5 | KJ13: =SUMPRODUCT(KJ2:KJ11,Weights!B$5:K$5)*Parameters!$B$5 | KK13: =SUMPRODUCT(KK2:KK11,Weights!B$5:K$5)*Parameters!$B$5 | KL13: =SUMPRODUCT(KL2:KL11,Weights!B$5:K$5)*Parameters!$B$5 | KM13: =SUMPRODUCT(KM2:KM11,Weights!B$5:K$5)*Parameters!$B$5 | KN13: =SUMPRODUCT(KN2:KN11,Weights!B$5:K$5)*Parameters!$B$5 | KO13: =SUMPRODUCT(KO2:KO11,Weights!B$5:K$5)*Parameters!$B$5 | KP13: =SUMPRODUCT(KP2:KP11,Weights!B$5:K$5)*Parameters!$B$5 | KQ13: =SUMPRODUCT(KQ2:KQ11,Weights!B$5:K$5)*Parameters!$B$5 | KR13: =SUMPRODUCT(KR2:KR11,Weights!B$5:K$5)*Parameters!$B$5 | KS13: =SUMPRODUCT(KS2:KS11,Weights!B$5:K$5)*Parameters!$B$5 | KT13: =SUMPRODUCT(KT2:KT11,Weights!B$5:K$5)*Parameters!$B$5 | KU13: =SUMPRODUCT(KU2:KU11,Weights!B$5:K$5)*Parameters!$B$5 | KV13: =SUMPRODUCT(KV2:KV11,Weights!B$5:K$5)*Parameters!$B$5 | KW13: =SUMPRODUCT(KW2:KW11,Weights!B$5:K$5)*Parameters!$B$5 | KX13: =SUMPRODUCT(KX2:KX11,Weights!B$5:K$5)*Parameters!$B$5 | KY13: =SUMPRODUCT(KY2:KY11,Weights!B$5:K$5)*Parameters!$B$5 | KZ13: =SUMPRODUCT(KZ2:KZ11,Weights!B$5:K$5)*Parameters!$B$5 | LA13: =SUMPRODUCT(LA2:LA11,Weights!B$5:K$5)*Parameters!$B$5 | LB13: =SUMPRODUCT(LB2:LB11,Weights!B$5:K$5)*Parameters!$B$5 | LC13: =SUMPRODUCT(LC2:LC11,Weights!B$5:K$5)*Parameters!$B$5 | LD13: =SUMPRODUCT(LD2:LD11,Weights!B$5:K$5)*Parameters!$B$5 | LE13: =SUMPRODUCT(LE2:LE11,Weights!B$5:K$5)*Parameters!$B$5 | LF13: =SUMPRODUCT(LF2:LF11,Weights!B$5:K$5)*Parameters!$B$5 | LG13: =SUMPRODUCT(LG2:LG11,Weights!B$5:K$5)*Parameters!$B$5 | LH13: =SUMPRODUCT(LH2:LH11,Weights!B$5:K$5)*Parameters!$B$5 | LI13: =SUMPRODUCT(LI2:LI11,Weights!B$5:K$5)*Parameters!$B$5 | LJ13: =SUMPRODUCT(LJ2:LJ11,Weights!B$5:K$5)*Parameters!$B$5 | LK13: =SUMPRODUCT(LK2:LK11,Weights!B$5:K$5)*Parameters!$B$5 | LL13: =SUMPRODUCT(LL2:LL11,Weights!B$5:K$5)*Parameters!$B$5 | LM13: =SUMPRODUCT(LM2:LM11,Weights!B$5:K$5)*Parameters!$B$5 | LN13: =SUMPRODUCT(LN2:LN11,Weights!B$5:K$5)*Parameters!$B$5 | LO13: =SUMPRODUCT(LO2:LO11,Weights!B$5:K$5)*Parameters!$B$5 | LP13: =SUMPRODUCT(LP2:LP11,Weights!B$5:K$5)*Parameters!$B$5 | LQ13: =SUMPRODUCT(LQ2:LQ11,Weights!B$5:K$5)*Parameters!$B$5 | LR13: =SUMPRODUCT(LR2:LR11,Weights!B$5:K$5)*Parameters!$B$5 | LS13: =SUMPRODUCT(LS2:LS11,Weights!B$5:K$5)*Parameters!$B$5 | LT13: =SUMPRODUCT(LT2:LT11,Weights!B$5:K$5)*Parameters!$B$5 | LU13: =SUMPRODUCT(LU2:LU11,Weights!B$5:K$5)*Parameters!$B$5 | LV13: =SUMPRODUCT(LV2:LV11,Weights!B$5:K$5)*Parameters!$B$5 | LW13: =SUMPRODUCT(LW2:LW11,Weights!B$5:K$5)*Parameters!$B$5 | LX13: =SUMPRODUCT(LX2:LX11,Weights!B$5:K$5)*Parameters!$B$5 | LY13: =SUMPRODUCT(LY2:LY11,Weights!B$5:K$5)*Parameters!$B$5 | LZ13: =SUMPRODUCT(LZ2:LZ11,Weights!B$5:K$5)*Parameters!$B$5 | MA13: =SUMPRODUCT(MA2:MA11,Weights!B$5:K$5)*Parameters!$B$5 | MB13: =SUMPRODUCT(MB2:MB11,Weights!B$5:K$5)*Parameters!$B$5 | MC13: =SUMPRODUCT(MC2:MC11,Weights!B$5:K$5)*Parameters!$B$5 | MD13: =SUMPRODUCT(MD2:MD11,Weights!B$5:K$5)*Parameters!$B$5 | ME13: =SUMPRODUCT(ME2:ME11,Weights!B$5:K$5)*Parameters!$B$5 | MF13: =SUMPRODUCT(MF2:MF11,Weights!B$5:K$5)*Parameters!$B$5 | MG13: =SUMPRODUCT(MG2:MG11,Weights!B$5:K$5)*Parameters!$B$5 | MH13: =SUMPRODUCT(MH2:MH11,Weights!B$5:K$5)*Parameters!$B$5 | MI13: =SUMPRODUCT(MI2:MI11,Weights!B$5:K$5)*Parameters!$B$5 | MJ13: =SUMPRODUCT(MJ2:MJ11,Weights!B$5:K$5)*Parameters!$B$5 | MK13: =SUMPRODUCT(MK2:MK11,Weights!B$5:K$5)*Parameters!$B$5 | ML13: =SUMPRODUCT(ML2:ML11,Weights!B$5:K$5)*Parameters!$B$5 | MM13: =SUMPRODUCT(MM2:MM11,Weights!B$5:K$5)*Parameters!$B$5 | MN13: =SUMPRODUCT(MN2:MN11,Weights!B$5:K$5)*Parameters!$B$5 | MO13: =SUMPRODUCT(MO2:MO11,Weights!B$5:K$5)*Parameters!$B$5 | MP13: =SUMPRODUCT(MP2:MP11,Weights!B$5:K$5)*Parameters!$B$5 | MQ13: =SUMPRODUCT(MQ2:MQ11,Weights!B$5:K$5)*Parameters!$B$5 | MR13: =SUMPRODUCT(MR2:MR11,Weights!B$5:K$5)*Parameters!$B$5 | MS13: =SUMPRODUCT(MS2:MS11,Weights!B$5:K$5)*Parameters!$B$5 | MT13: =SUMPRODUCT(MT2:MT11,Weights!B$5:K$5)*Parameters!$B$5 | MU13: =SUMPRODUCT(MU2:MU11,Weights!B$5:K$5)*Parameters!$B$5 | MV13: =SUMPRODUCT(MV2:MV11,Weights!B$5:K$5)*Parameters!$B$5 | MW13: =SUMPRODUCT(MW2:MW11,Weights!B$5:K$5)*Parameters!$B$5 | MX13: =SUMPRODUCT(MX2:MX11,Weights!B$5:K$5)*Parameters!$B$5 | MY13: =SUMPRODUCT(MY2:MY11,Weights!B$5:K$5)*Parameters!$B$5 | MZ13: =SUMPRODUCT(MZ2:MZ11,Weights!B$5:K$5)*Parameters!$B$5 | NA13: =SUMPRODUCT(NA2:NA11,Weights!B$5:K$5)*Parameters!$B$5 | NB13: =SUMPRODUCT(NB2:NB11,Weights!B$5:K$5)*Parameters!$B$5 | NC13: =SUMPRODUCT(NC2:NC11,Weights!B$5:K$5)*Parameters!$B$5 | ND13: =SUMPRODUCT(ND2:ND11,Weights!B$5:K$5)*Parameters!$B$5 | NE13: =SUMPRODUCT(NE2:NE11,Weights!B$5:K$5)*Parameters!$B$5 | NF13: =SUMPRODUCT(NF2:NF11,Weights!B$5:K$5)*Parameters!$B$5 | NG13: =SUMPRODUCT(NG2:NG11,Weights!B$5:K$5)*Parameters!$B$5 | NH13: =SUMPRODUCT(NH2:NH11,Weights!B$5:K$5)*Parameters!$B$5 | NI13: =SUMPRODUCT(NI2:NI11,Weights!B$5:K$5)*Parameters!$B$5 | NJ13: =SUMPRODUCT(NJ2:NJ11,Weights!B$5:K$5)*Parameters!$B$5 | NK13: =SUMPRODUCT(NK2:NK11,Weights!B$5:K$5)*Parameters!$B$5 | NL13: =SUMPRODUCT(NL2:NL11,Weights!B$5:K$5)*Parameters!$B$5 | NM13: =SUMPRODUCT(NM2:NM11,Weights!B$5:K$5)*Parameters!$B$5 | NN13: =SUMPRODUCT(NN2:NN11,Weights!B$5:K$5)*Parameters!$B$5 | NO13: =SUMPRODUCT(NO2:NO11,Weights!B$5:K$5)*Parameters!$B$5 | NP13: =SUMPRODUCT(NP2:NP11,Weights!B$5:K$5)*Parameters!$B$5 | NQ13: =SUMPRODUCT(NQ2:NQ11,Weights!B$5:K$5)*Parameters!$B$5 | NR13: =SUMPRODUCT(NR2:NR11,Weights!B$5:K$5)*Parameters!$B$5 | NS13: =SUMPRODUCT(NS2:NS11,Weights!B$5:K$5)*Parameters!$B$5 | NT13: =SUMPRODUCT(NT2:NT11,Weights!B$5:K$5)*Parameters!$B$5 | NU13: =SUMPRODUCT(NU2:NU11,Weights!B$5:K$5)*Parameters!$B$5 | NV13: =SUMPRODUCT(NV2:NV11,Weights!B$5:K$5)*Parameters!$B$5 | NW13: =SUMPRODUCT(NW2:NW11,Weights!B$5:K$5)*Parameters!$B$5 | NX13: =SUMPRODUCT(NX2:NX11,Weights!B$5:K$5)*Parameters!$B$5 | NY13: =SUMPRODUCT(NY2:NY11,Weights!B$5:K$5)*Parameters!$B$5 | NZ13: =SUMPRODUCT(NZ2:NZ11,Weights!B$5:K$5)*Parameters!$B$5 | OA13: =SUMPRODUCT(OA2:OA11,Weights!B$5:K$5)*Parameters!$B$5 | OB13: =SUMPRODUCT(OB2:OB11,Weights!B$5:K$5)*Parameters!$B$5 | OC13: =SUMPRODUCT(OC2:OC11,Weights!B$5:K$5)*Parameters!$B$5 | OD13: =SUMPRODUCT(OD2:OD11,Weights!B$5:K$5)*Parameters!$B$5 | OE13: =SUMPRODUCT(OE2:OE11,Weights!B$5:K$5)*Parameters!$B$5 | OF13: =SUMPRODUCT(OF2:OF11,Weights!B$5:K$5)*Parameters!$B$5 | OG13: =SUMPRODUCT(OG2:OG11,Weights!B$5:K$5)*Parameters!$B$5 | OH13: =SUMPRODUCT(OH2:OH11,Weights!B$5:K$5)*Parameters!$B$5 | OI13: =SUMPRODUCT(OI2:OI11,Weights!B$5:K$5)*Parameters!$B$5 | OJ13: =SUMPRODUCT(OJ2:OJ11,Weights!B$5:K$5)*Parameters!$B$5 | OK13: =SUMPRODUCT(OK2:OK11,Weights!B$5:K$5)*Parameters!$B$5 | OL13: =SUMPRODUCT(OL2:OL11,Weights!B$5:K$5)*Parameters!$B$5 | OM13: =SUMPRODUCT(OM2:OM11,Weights!B$5:K$5)*Parameters!$B$5 | ON13: =SUMPRODUCT(ON2:ON11,Weights!B$5:K$5)*Parameters!$B$5 | OO13: =SUMPRODUCT(OO2:OO11,Weights!B$5:K$5)*Parameters!$B$5 | OP13: =SUMPRODUCT(OP2:OP11,Weights!B$5:K$5)*Parameters!$B$5 | OQ13: =SUMPRODUCT(OQ2:OQ11,Weights!B$5:K$5)*Parameters!$B$5 | OR13: =SUMPRODUCT(OR2:OR11,Weights!B$5:K$5)*Parameters!$B$5 | OS13: =SUMPRODUCT(OS2:OS11,Weights!B$5:K$5)*Parameters!$B$5 | OT13: =SUMPRODUCT(OT2:OT11,Weights!B$5:K$5)*Parameters!$B$5 | OU13: =SUMPRODUCT(OU2:OU11,Weights!B$5:K$5)*Parameters!$B$5 | OV13: =SUMPRODUCT(OV2:OV11,Weights!B$5:K$5)*Parameters!$B$5 | OW13: =SUMPRODUCT(OW2:OW11,Weights!B$5:K$5)*Parameters!$B$5 | OX13: =SUMPRODUCT(OX2:OX11,Weights!B$5:K$5)*Parameters!$B$5 | OY13: =SUMPRODUCT(OY2:OY11,Weights!B$5:K$5)*Parameters!$B$5 | OZ13: =SUMPRODUCT(OZ2:OZ11,Weights!B$5:K$5)*Parameters!$B$5 | PA13: =SUMPRODUCT(PA2:PA11,Weights!B$5:K$5)*Parameters!$B$5 | PB13: =SUMPRODUCT(PB2:PB11,Weights!B$5:K$5)*Parameters!$B$5 | PC13: =SUMPRODUCT(PC2:PC11,Weights!B$5:K$5)*Parameters!$B$5 | PD13: =SUMPRODUCT(PD2:PD11,Weights!B$5:K$5)*Parameters!$B$5 | PE13: =SUMPRODUCT(PE2:PE11,Weights!B$5:K$5)*Parameters!$B$5 | PF13: =SUMPRODUCT(PF2:PF11,Weights!B$5:K$5)*Parameters!$B$5 | PG13: =SUMPRODUCT(PG2:PG11,Weights!B$5:K$5)*Parameters!$B$5 | PH13: =SUMPRODUCT(PH2:PH11,Weights!B$5:K$5)*Parameters!$B$5 | PI13: =SUMPRODUCT(PI2:PI11,Weights!B$5:K$5)*Parameters!$B$5 | PJ13: =SUMPRODUCT(PJ2:PJ11,Weights!B$5:K$5)*Parameters!$B$5 | PK13: =SUMPRODUCT(PK2:PK11,Weights!B$5:K$5)*Parameters!$B$5 | PL13: =SUMPRODUCT(PL2:PL11,Weights!B$5:K$5)*Parameters!$B$5 | PM13: =SUMPRODUCT(PM2:PM11,Weights!B$5:K$5)*Parameters!$B$5 | PN13: =SUMPRODUCT(PN2:PN11,Weights!B$5:K$5)*Parameters!$B$5 | PO13: =SUMPRODUCT(PO2:PO11,Weights!B$5:K$5)*Parameters!$B$5 | PP13: =SUMPRODUCT(PP2:PP11,Weights!B$5:K$5)*Parameters!$B$5 | PQ13: =SUMPRODUCT(PQ2:PQ11,Weights!B$5:K$5)*Parameters!$B$5 | PR13: =SUMPRODUCT(PR2:PR11,Weights!B$5:K$5)*Parameters!$B$5 | PS13: =SUMPRODUCT(PS2:PS11,Weights!B$5:K$5)*Parameters!$B$5 | PT13: =SUMPRODUCT(PT2:PT11,Weights!B$5:K$5)*Parameters!$B$5 | PU13: =SUMPRODUCT(PU2:PU11,Weights!B$5:K$5)*Parameters!$B$5 | PV13: =SUMPRODUCT(PV2:PV11,Weights!B$5:K$5)*Parameters!$B$5 | PW13: =SUMPRODUCT(PW2:PW11,Weights!B$5:K$5)*Parameters!$B$5 | PX13: =SUMPRODUCT(PX2:PX11,Weights!B$5:K$5)*Parameters!$B$5 | PY13: =SUMPRODUCT(PY2:PY11,Weights!B$5:K$5)*Parameters!$B$5 | PZ13: =SUMPRODUCT(PZ2:PZ11,Weights!B$5:K$5)*Parameters!$B$5 | QA13: =SUMPRODUCT(QA2:QA11,Weights!B$5:K$5)*Parameters!$B$5 | QB13: =SUMPRODUCT(QB2:QB11,Weights!B$5:K$5)*Parameters!$B$5 | QC13: =SUMPRODUCT(QC2:QC11,Weights!B$5:K$5)*Parameters!$B$5 | QD13: =SUMPRODUCT(QD2:QD11,Weights!B$5:K$5)*Parameters!$B$5 | QE13: =SUMPRODUCT(QE2:QE11,Weights!B$5:K$5)*Parameters!$B$5 | QF13: =SUMPRODUCT(QF2:QF11,Weights!B$5:K$5)*Parameters!$B$5 | QG13: =SUMPRODUCT(QG2:QG11,Weights!B$5:K$5)*Parameters!$B$5 | QH13: =SUMPRODUCT(QH2:QH11,Weights!B$5:K$5)*Parameters!$B$5 | QI13: =SUMPRODUCT(QI2:QI11,Weights!B$5:K$5)*Parameters!$B$5 | QJ13: =SUMPRODUCT(QJ2:QJ11,Weights!B$5:K$5)*Parameters!$B$5 | QK13: =SUMPRODUCT(QK2:QK11,Weights!B$5:K$5)*Parameters!$B$5 | QL13: =SUMPRODUCT(QL2:QL11,Weights!B$5:K$5)*Parameters!$B$5 | QM13: =SUMPRODUCT(QM2:QM11,Weights!B$5:K$5)*Parameters!$B$5 | QN13: =SUMPRODUCT(QN2:QN11,Weights!B$5:K$5)*Parameters!$B$5 | QO13: =SUMPRODUCT(QO2:QO11,Weights!B$5:K$5)*Parameters!$B$5 | QP13: =SUMPRODUCT(QP2:QP11,Weights!B$5:K$5)*Parameters!$B$5 | QQ13: =SUMPRODUCT(QQ2:QQ11,Weights!B$5:K$5)*Parameters!$B$5 | QR13: =SUMPRODUCT(QR2:QR11,Weights!B$5:K$5)*Parameters!$B$5 | QS13: =SUMPRODUCT(QS2:QS11,Weights!B$5:K$5)*Parameters!$B$5 | QT13: =SUMPRODUCT(QT2:QT11,Weights!B$5:K$5)*Parameters!$B$5 | QU13: =SUMPRODUCT(QU2:QU11,Weights!B$5:K$5)*Parameters!$B$5 | QV13: =SUMPRODUCT(QV2:QV11,Weights!B$5:K$5)*Parameters!$B$5 | QW13: =SUMPRODUCT(QW2:QW11,Weights!B$5:K$5)*Parameters!$B$5 | QX13: =SUMPRODUCT(QX2:QX11,Weights!B$5:K$5)*Parameters!$B$5 | QY13: =SUMPRODUCT(QY2:QY11,Weights!B$5:K$5)*Parameters!$B$5 | QZ13: =SUMPRODUCT(QZ2:QZ11,Weights!B$5:K$5)*Parameters!$B$5 | RA13: =SUMPRODUCT(RA2:RA11,Weights!B$5:K$5)*Parameters!$B$5 | RB13: =SUMPRODUCT(RB2:RB11,Weights!B$5:K$5)*Parameters!$B$5 | RC13: =SUMPRODUCT(RC2:RC11,Weights!B$5:K$5)*Parameters!$B$5 | RD13: =SUMPRODUCT(RD2:RD11,Weights!B$5:K$5)*Parameters!$B$5 | RE13: =SUMPRODUCT(RE2:RE11,Weights!B$5:K$5)*Parameters!$B$5 | RF13: =SUMPRODUCT(RF2:RF11,Weights!B$5:K$5)*Parameters!$B$5 | RG13: =SUMPRODUCT(RG2:RG11,Weights!B$5:K$5)*Parameters!$B$5 | RH13: =SUMPRODUCT(RH2:RH11,Weights!B$5:K$5)*Parameters!$B$5 | RI13: =SUMPRODUCT(RI2:RI11,Weights!B$5:K$5)*Parameters!$B$5 | RJ13: =SUMPRODUCT(RJ2:RJ11,Weights!B$5:K$5)*Parameters!$B$5 | RK13: =SUMPRODUCT(RK2:RK11,Weights!B$5:K$5)*Parameters!$B$5 | RL13: =SUMPRODUCT(RL2:RL11,Weights!B$5:K$5)*Parameters!$B$5 | RM13: =SUMPRODUCT(RM2:RM11,Weights!B$5:K$5)*Parameters!$B$5 | RN13: =SUMPRODUCT(RN2:RN11,Weights!B$5:K$5)*Parameters!$B$5 | RO13: =SUMPRODUCT(RO2:RO11,Weights!B$5:K$5)*Parameters!$B$5 | RP13: =SUMPRODUCT(RP2:RP11,Weights!B$5:K$5)*Parameters!$B$5 | RQ13: =SUMPRODUCT(RQ2:RQ11,Weights!B$5:K$5)*Parameters!$B$5 | RR13: =SUMPRODUCT(RR2:RR11,Weights!B$5:K$5)*Parameters!$B$5 | RS13: =SUMPRODUCT(RS2:RS11,Weights!B$5:K$5)*Parameters!$B$5 | RT13: =SUMPRODUCT(RT2:RT11,Weights!B$5:K$5)*Parameters!$B$5 | RU13: =SUMPRODUCT(RU2:RU11,Weights!B$5:K$5)*Parameters!$B$5 | RV13: =SUMPRODUCT(RV2:RV11,Weights!B$5:K$5)*Parameters!$B$5 | RW13: =SUMPRODUCT(RW2:RW11,Weights!B$5:K$5)*Parameters!$B$5 | RX13: =SUMPRODUCT(RX2:RX11,Weights!B$5:K$5)*Parameters!$B$5 | RY13: =SUMPRODUCT(RY2:RY11,Weights!B$5:K$5)*Parameters!$B$5 | RZ13: =SUMPRODUCT(RZ2:RZ11,Weights!B$5:K$5)*Parameters!$B$5 | SA13: =SUMPRODUCT(SA2:SA11,Weights!B$5:K$5)*Parameters!$B$5 | SB13: =SUMPRODUCT(SB2:SB11,Weights!B$5:K$5)*Parameters!$B$5 | SC13: =SUMPRODUCT(SC2:SC11,Weights!B$5:K$5)*Parameters!$B$5 | SD13: =SUMPRODUCT(SD2:SD11,Weights!B$5:K$5)*Parameters!$B$5 | SE13: =SUMPRODUCT(SE2:SE11,Weights!B$5:K$5)*Parameters!$B$5 | SF13: =SUMPRODUCT(SF2:SF11,Weights!B$5:K$5)*Parameters!$B$5 | SG13: =SUMPRODUCT(SG2:SG11,Weights!B$5:K$5)*Parameters!$B$5

Sheet Sim_2_やや集中
A1: 債務者 \ Trial | B1: Trial 1 | C1: Trial 2 | D1: Trial 3 | E1: Trial 4 | F1: Trial 5 | G1: Trial 6 | H1: Trial 7 | I1: Trial 8 | J1: Trial 9 | K1: Trial 10 | L1: Trial 11 | M1: Trial 12 | N1: Trial 13 | O1: Trial 14 | P1: Trial 15 | Q1: Trial 16 | R1: Trial 17 | S1: Trial 18 | T1: Trial 19 | U1: Trial 20 | V1: Trial 21 | W1: Trial 22 | X1: Trial 23 | Y1: Trial 24 | Z1: Trial 25 | AA1: Trial 26 | AB1: Trial 27 | AC1: Trial 28 | AD1: Trial 29 | AE1: Trial 30 | AF1: Trial 31 | AG1: Trial 32 | AH1: Trial 33 | AI1: Trial 34 | AJ1: Trial 35 | AK1: Trial 36 | AL1: Trial 37 | AM1: Trial 38 | AN1: Trial 39 | AO1: Trial 40 | AP1: Trial 41 | AQ1: Trial 42 | AR1: Trial 43 | AS1: Trial 44 | AT1: Trial 45 | AU1: Trial 46 | AV1: Trial 47 | AW1: Trial 48 | AX1: Trial 49 | AY1: Trial 50 | AZ1: Trial 51 | BA1: Trial 52 | BB1: Trial 53 | BC1: Trial 54 | BD1: Trial 55 | BE1: Trial 56 | BF1: Trial 57 | BG1: Trial 58 | BH1: Trial 59 | BI1: Trial 60 | BJ1: Trial 61 | BK1: Trial 62 | BL1: Trial 63 | BM1: Trial 64 | BN1: Trial 65 | BO1: Trial 66 | BP1: Trial 67 | BQ1: Trial 68 | BR1: Trial 69 | BS1: Trial 70 | BT1: Trial 71 | BU1: Trial 72 | BV1: Trial 73 | BW1: Trial 74 | BX1: Trial 75 | BY1: Trial 76 | BZ1: Trial 77 | CA1: Trial 78 | CB1: Trial 79 | CC1: Trial 80 | CD1: Trial 81 | CE1: Trial 82 | CF1: Trial 83 | CG1: Trial 84 | CH1: Trial 85 | CI1: Trial 86 | CJ1: Trial 87 | CK1: Trial 88 | CL1: Trial 89 | CM1: Trial 90 | CN1: Trial 91 | CO1: Trial 92 | CP1: Trial 93 | CQ1: Trial 94 | CR1: Trial 95 | CS1: Trial 96 | CT1: Trial 97 | CU1: Trial 98 | CV1: Trial 99 | CW1: Trial 100 | CX1: Trial 101 | CY1: Trial 102 | CZ1: Trial 103 | DA1: Trial 104 | DB1: Trial 105 | DC1: Trial 106 | DD1: Trial 107 | DE1: Trial 108 | DF1: Trial 109 | DG1: Trial 110 | DH1: Trial 111 | DI1: Trial 112 | DJ1: Trial 113 | DK1: Trial 114 | DL1: Trial 115 | DM1: Trial 116 | DN1: Trial 117 | DO1: Trial 118 | DP1: Trial 119 | DQ1: Trial 120 | DR1: Trial 121 | DS1: Trial 122 | DT1: Trial 123 | DU1: Trial 124 | DV1: Trial 125 | DW1: Trial 126 | DX1: Trial 127 | DY1: Trial 128 | DZ1: Trial 129 | EA1: Trial 130 | EB1: Trial 131 | EC1: Trial 132 | ED1: Trial 133 | EE1: Trial 134 | EF1: Trial 135 | EG1: Trial 136 | EH1: Trial 137 | EI1: Trial 138 | EJ1: Trial 139 | EK1: Trial 140 | EL1: Trial 141 | EM1: Trial 142 | EN1: Trial 143 | EO1: Trial 144 | EP1: Trial 145 | EQ1: Trial 146 | ER1: Trial 147 | ES1: Trial 148 | ET1: Trial 149 | EU1: Trial 150 | EV1: Trial 151 | EW1: Trial 152 | EX1: Trial 153 | EY1: Trial 154 | EZ1: Trial 155 | FA1: Trial 156 | FB1: Trial 157 | FC1: Trial 158 | FD1: Trial 159 | FE1: Trial 160 | FF1: Trial 161 | FG1: Trial 162 | FH1: Trial 163 | FI1: Trial 164 | FJ1: Trial 165 | FK1: Trial 166 | FL1: Trial 167 | FM1: Trial 168 | FN1: Trial 169 | FO1: Trial 170 | FP1: Trial 171 | FQ1: Trial 172 | FR1: Trial 173 | FS1: Trial 174 | FT1: Trial 175 | FU1: Trial 176 | FV1: Trial 177 | FW1: Trial 178 | FX1: Trial 179 | FY1: Trial 180 | FZ1: Trial 181 | GA1: Trial 182 | GB1: Trial 183 | GC1: Trial 184 | GD1: Trial 185 | GE1: Trial 186 | GF1: Trial 187 | GG1: Trial 188 | GH1: Trial 189 | GI1: Trial 190 | GJ1: Trial 191 | GK1: Trial 192 | GL1: Trial 193 | GM1: Trial 194 | GN1: Trial 195 | GO1: Trial 196 | GP1: Trial 197 | GQ1: Trial 198 | GR1: Trial 199 | GS1: Trial 200 | GT1: Trial 201 | GU1: Trial 202 | GV1: Trial 203 | GW1: Trial 204 | GX1: Trial 205 | GY1: Trial 206 | GZ1: Trial 207 | HA1: Trial 208 | HB1: Trial 209 | HC1: Trial 210 | HD1: Trial 211 | HE1: Trial 212 | HF1: Trial 213 | HG1: Trial 214 | HH1: Trial 215 | HI1: Trial 216 | HJ1: Trial 217 | HK1: Trial 218 | HL1: Trial 219 | HM1: Trial 220 | HN1: Trial 221 | HO1: Trial 222 | HP1: Trial 223 | HQ1: Trial 224 | HR1: Trial 225 | HS1: Trial 226 | HT1: Trial 227 | HU1: Trial 228 | HV1: Trial 229 | HW1: Trial 230 | HX1: Trial 231 | HY1: Trial 232 | HZ1: Trial 233 | IA1: Trial 234 | IB1: Trial 235 | IC1: Trial 236 | ID1: Trial 237 | IE1: Trial 238 | IF1: Trial 239 | IG1: Trial 240 | IH1: Trial 241 | II1: Trial 242 | IJ1: Trial 243 | IK1: Trial 244 | IL1: Trial 245 | IM1: Trial 246 | IN1: Trial 247 | IO1: Trial 248 | IP1: Trial 249 | IQ1: Trial 250 | IR1: Trial 251 | IS1: Trial 252 | IT1: Trial 253 | IU1: Trial 254 | IV1: Trial 255 | IW1: Trial 256 | IX1: Trial 257 | IY1: Trial 258 | IZ1: Trial 259 | JA1: Trial 260 | JB1: Trial 261 | JC1: Trial 262 | JD1: Trial 263 | JE1: Trial 264 | JF1: Trial 265 | JG1: Trial 266 | JH1: Trial 267 | JI1: Trial 268 | JJ1: Trial 269 | JK1: Trial 270 | JL1: Trial 271 | JM1: Trial 272 | JN1: Trial 273 | JO1: Trial 274 | JP1: Trial 275 | JQ1: Trial 276 | JR1: Trial 277 | JS1: Trial 278 | JT1: Trial 279 | JU1: Trial 280 | JV1: Trial 281 | JW1: Trial 282 | JX1: Trial 283 | JY1: Trial 284 | JZ1: Trial 285 | KA1: Trial 286 | KB1: Trial 287 | KC1: Trial 288 | KD1: Trial 289 | KE1: Trial 290 | KF1: Trial 291 | KG1: Trial 292 | KH1: Trial 293 | KI1: Trial 294 | KJ1: Trial 295 | KK1: Trial 296 | KL1: Trial 297 | KM1: Trial 298 | KN1: Trial 299 | KO1: Trial 300 | KP1: Trial 301 | KQ1: Trial 302 | KR1: Trial 303 | KS1: Trial 304 | KT1: Trial 305 | KU1: Trial 306 | KV1: Trial 307 | KW1: Trial 308 | KX1: Trial 309 | KY1: Trial 310 | KZ1: Trial 311 | LA1: Trial 312 | LB1: Trial 313 | LC1: Trial 314 | LD1: Trial 315 | LE1: Trial 316 | LF1: Trial 317 | LG1: Trial 318 | LH1: Trial 319 | LI1: Trial 320 | LJ1: Trial 321 | LK1: Trial 322 | LL1: Trial 323 | LM1: Trial 324 | LN1: Trial 325 | LO1: Trial 326 | LP1: Trial 327 | LQ1: Trial 328 | LR1: Trial 329 | LS1: Trial 330 | LT1: Trial 331 | LU1: Trial 332 | LV1: Trial 333 | LW1: Trial 334 | LX1: Trial 335 | LY1: Trial 336 | LZ1: Trial 337 | MA1: Trial 338 | MB1: Trial 339 | MC1: Trial 340 | MD1: Trial 341 | ME1: Trial 342 | MF1: Trial 343 | MG1: Trial 344 | MH1: Trial 345 | MI1: Trial 346 | MJ1: Trial 347 | MK1: Trial 348 | ML1: Trial 349 | MM1: Trial 350 | MN1: Trial 351 | MO1: Trial 352 | MP1: Trial 353 | MQ1: Trial 354 | MR1: Trial 355 | MS1: Trial 356 | MT1: Trial 357 | MU1: Trial 358 | MV1: Trial 359 | MW1: Trial 360 | MX1: Trial 361 | MY1: Trial 362 | MZ1: Trial 363 | NA1: Trial 364 | NB1: Trial 365 | NC1: Trial 366 | ND1: Trial 367 | NE1: Trial 368 | NF1: Trial 369 | NG1: Trial 370 | NH1: Trial 371 | NI1: Trial 372 | NJ1: Trial 373 | NK1: Trial 374 | NL1: Trial 375 | NM1: Trial 376 | NN1: Trial 377 | NO1: Trial 378 | NP1: Trial 379 | NQ1: Trial 380 | NR1: Trial 381 | NS1: Trial 382 | NT1: Trial 383 | NU1: Trial 384 | NV1: Trial 385 | NW1: Trial 386 | NX1: Trial 387 | NY1: Trial 388 | NZ1: Trial 389 | OA1: Trial 390 | OB1: Trial 391 | OC1: Trial 392 | OD1: Trial 393 | OE1: Trial 394 | OF1: Trial 395 | OG1: Trial 396 | OH1: Trial 397 | OI1: Trial 398 | OJ1: Trial 399 | OK1: Trial 400 | OL1: Trial 401 | OM1: Trial 402 | ON1: Trial 403 | OO1: Trial 404 | OP1: Trial 405 | OQ1: Trial 406 | OR1: Trial 407 | OS1: Trial 408 | OT1: Trial 409 | OU1: Trial 410 | OV1: Trial 411 | OW1: Trial 412 | OX1: Trial 413 | OY1: Trial 414 | OZ1: Trial 415 | PA1: Trial 416 | PB1: Trial 417 | PC1: Trial 418 | PD1: Trial 419 | PE1: Trial 420 | PF1: Trial 421 | PG1: Trial 422 | PH1: Trial 423 | PI1: Trial 424 | PJ1: Trial 425 | PK1: Trial 426 | PL1: Trial 427 | PM1: Trial 428 | PN1: Trial 429 | PO1: Trial 430 | PP1: Trial 431 | PQ1: Trial 432 | PR1: Trial 433 | PS1: Trial 434 | PT1: Trial 435 | PU1: Trial 436 | PV1: Trial 437 | PW1: Trial 438 | PX1: Trial 439 | PY1: Trial 440 | PZ1: Trial 441 | QA1: Trial 442 | QB1: Trial 443 | QC1: Trial 444 | QD1: Trial 445 | QE1: Trial 446 | QF1: Trial 447 | QG1: Trial 448 | QH1: Trial 449 | QI1: Trial 450 | QJ1: Trial 451 | QK1: Trial 452 | QL1: Trial 453 | QM1: Trial 454 | QN1: Trial 455 | QO1: Trial 456 | QP1: Trial 457 | QQ1: Trial 458 | QR1: Trial 459 | QS1: Trial 460 | QT1: Trial 461 | QU1: Trial 462 | QV1: Trial 463 | QW1: Trial 464 | QX1: Trial 465 | QY1: Trial 466 | QZ1: Trial 467 | RA1: Trial 468 | RB1: Trial 469 | RC1: Trial 470 | RD1: Trial 471 | RE1: Trial 472 | RF1: Trial 473 | RG1: Trial 474 | RH1: Trial 475 | RI1: Trial 476 | RJ1: Trial 477 | RK1: Trial 478 | RL1: Trial 479 | RM1: Trial 480 | RN1: Trial 481 | RO1: Trial 482 | RP1: Trial 483 | RQ1: Trial 484 | RR1: Trial 485 | RS1: Trial 486 | RT1: Trial 487 | RU1: Trial 488 | RV1: Trial 489 | RW1: Trial 490 | RX1: Trial 491 | RY1: Trial 492 | RZ1: Trial 493 | SA1: Trial 494 | SB1: Trial 495 | SC1: Trial 496 | SD1: Trial 497 | SE1: Trial 498 | SF1: Trial 499 | SG1: Trial 500
A2: 債務者1 | B2: =IF(RAND()<Parameters!$B$4,1,0) | C2: =IF(RAND()<Parameters!$B$4,1,0) | D2: =IF(RAND()<Parameters!$B$4,1,0) | E2: =IF(RAND()<Parameters!$B$4,1,0) | F2: =IF(RAND()<Parameters!$B$4,1,0) | G2: =IF(RAND()<Parameters!$B$4,1,0) | H2: =IF(RAND()<Parameters!$B$4,1,0) | I2: =IF(RAND()<Parameters!$B$4,1,0) | ... SG2: =IF(RAND()<Parameters!$B$4,1,0)
A3: 債務者2 | B3: =IF(RAND()<Parameters!$B$4,1,0) | C3: =IF(RAND()<Parameters!$B$4,1,0) | D3: =IF(RAND()<Parameters!$B$4,1,0) | E3: =IF(RAND()<Parameters!$B$4,1,0) | F3: =IF(RAND()<Parameters!$B$4,1,0) | G3: =IF(RAND()<Parameters!$B$4,1,0) | H3: =IF(RAND()<Parameters!$B$4,1,0) | I3: =IF(RAND()<Parameters!$B$4,1,0) | ... SG3: =IF(RAND()<Parameters!$B$4,1,0)
A4: 債務者3 | B4: =IF(RAND()<Parameters!$B$4,1,0) | C4: =IF(RAND()<Parameters!$B$4,1,0) | D4: =IF(RAND()<Parameters!$B$4,1,0) | E4: =IF(RAND()<Parameters!$B$4,1,0) | F4: =IF(RAND()<Parameters!$B$4,1,0) | G4: =IF(RAND()<Parameters!$B$4,1,0) | H4: =IF(RAND()<Parameters!$B$4,1,0) | I4: =IF(RAND()<Parameters!$B$4,1,0) | ... SG4: =IF(RAND()<Parameters!$B$4,1,0)
A5: 債務者4 | B5: =IF(RAND()<Parameters!$B$4,1,0) | C5: =IF(RAND()<Parameters!$B$4,1,0) | D5: =IF(RAND()<Parameters!$B$4,1,0) | E5: =IF(RAND()<Parameters!$B$4,1,0) | F5: =IF(RAND()<Parameters!$B$4,1,0) | G5: =IF(RAND()<Parameters!$B$4,1,0) | H5: =IF(RAND()<Parameters!$B$4,1,0) | I5: =IF(RAND()<Parameters!$B$4,1,0) | ... SG5: =IF(RAND()<Parameters!$B$4,1,0)
A6: 債務者5 | B6: =IF(RAND()<Parameters!$B$4,1,0) | C6: =IF(RAND()<Parameters!$B$4,1,0) | D6: =IF(RAND()<Parameters!$B$4,1,0) | E6: =IF(RAND()<Parameters!$B$4,1,0) | F6: =IF(RAND()<Parameters!$B$4,1,0) | G6: =IF(RAND()<Parameters!$B$4,1,0) | H6: =IF(RAND()<Parameters!$B$4,1,0) | I6: =IF(RAND()<Parameters!$B$4,1,0) | ... SG6: =IF(RAND()<Parameters!$B$4,1,0)
A7: 債務者6 | B7: =IF(RAND()<Parameters!$B$4,1,0) | C7: =IF(RAND()<Parameters!$B$4,1,0) | D7: =IF(RAND()<Parameters!$B$4,1,0) | E7: =IF(RAND()<Parameters!$B$4,1,0) | F7: =IF(RAND()<Parameters!$B$4,1,0) | G7: =IF(RAND()<Parameters!$B$4,1,0) | H7: =IF(RAND()<Parameters!$B$4,1,0) | I7: =IF(RAND()<Parameters!$B$4,1,0) | ... SG7: =IF(RAND()<Parameters!$B$4,1,0)
A8: 債務者7 | B8: =IF(RAND()<Parameters!$B$4,1,0) | C8: =IF(RAND()<Parameters!$B$4,1,0) | D8: =IF(RAND()<Parameters!$B$4,1,0) | E8: =IF(RAND()<Parameters!$B$4,1,0) | F8: =IF(RAND()<Parameters!$B$4,1,0) | G8: =IF(RAND()<Parameters!$B$4,1,0) | H8: =IF(RAND()<Parameters!$B$4,1,0) | I8: =IF(RAND()<Parameters!$B$4,1,0) | ... SG8: =IF(RAND()<Parameters!$B$4,1,0)
A9: 債務者8 | B9: =IF(RAND()<Parameters!$B$4,1,0) | C9: =IF(RAND()<Parameters!$B$4,1,0) | D9: =IF(RAND()<Parameters!$B$4,1,0) | E9: =IF(RAND()<Parameters!$B$4,1,0) | F9: =IF(RAND()<Parameters!$B$4,1,0) | G9: =IF(RAND()<Parameters!$B$4,1,0) | H9: =IF(RAND()<Parameters!$B$4,1,0) | I9: =IF(RAND()<Parameters!$B$4,1,0) | ... SG9: =IF(RAND()<Parameters!$B$4,1,0)
A10: 債務者9 | B10: =IF(RAND()<Parameters!$B$4,1,0) | C10: =IF(RAND()<Parameters!$B$4,1,0) | D10: =IF(RAND()<Parameters!$B$4,1,0) | E10: =IF(RAND()<Parameters!$B$4,1,0) | F10: =IF(RAND()<Parameters!$B$4,1,0) | G10: =IF(RAND()<Parameters!$B$4,1,0) | H10: =IF(RAND()<Parameters!$B$4,1,0) | I10: =IF(RAND()<Parameters!$B$4,1,0) | ... SG10: =IF(RAND()<Parameters!$B$4,1,0)
A11: 債務者10 | B11: =IF(RAND()<Parameters!$B$4,1,0) | C11: =IF(RAND()<Parameters!$B$4,1,0) | D11: =IF(RAND()<Parameters!$B$4,1,0) | E11: =IF(RAND()<Parameters!$B$4,1,0) | F11: =IF(RAND()<Parameters!$B$4,1,0) | G11: =IF(RAND()<Parameters!$B$4,1,0) | H11: =IF(RAND()<Parameters!$B$4,1,0) | I11: =IF(RAND()<Parameters!$B$4,1,0) | ... SG11: =IF(RAND()<Parameters!$B$4,1,0)
