Workbook

Sheet Parameters
A1: Monte Carlo Credit Risk Simulation
A3: Parameter | B3: Value | C3: Description
A4: Number of Simulations | B4: 500 | C4: Trials (press F9 to re-simulate)
A5: Region Factor Weight (w_r) | B5: 0.15 | C5: Correlation from regional factor
A6: Sector Factor Weight (w_s) | B6: 0.1 | C6: Correlation from sector factor
A7: HNWI Factor Weight (w_h) | B7: 0.05 | C7: Correlation from HNWI factor
A8: VaR Confidence Level | B8: 0.99 | C8: For Value-at-Risk calculation
A9: Idiosyncratic Weight (1-w_r-w_s-w_h) | B9: =1-B5-B6-B7 | C9: Remaining weight for idiosyncratic risk
A11: How to Use
A12: 1. Review/edit obligor data in the 'Obligors' sheet
A13: 2. Adjust factor weights above to change correlation structure
A14: 3. Press F9 (or Ctrl+Alt+F9) to recalculate = run a new simulation
A15: 4. View results in the 'Results' sheet
A16: 5. The 'Factors' sheet shows systematic factor draws per trial
A17: 6. The 'Simulation' sheet shows the correlated latent variables
A18: 7. The 'Defaults' sheet shows binary default indicators (1=default)
A19: 8. The 'Losses' sheet shows per-obligor loss amounts

Sheet Obligors
A1: ID | B1: Name | C1: Region | D1: Sector | E1: HNWI | F1: PD (%) | G1: EAD (M) | H1: LGD (%) | I1: Default Threshold
A2: OBL-001 | B2: Alpha Industries | C2: Asia | D2: Manufacturing | E2: No | F2: 0.015 | G2: 120 | H2: 0.45 | I2: =NORM.S.INV(F2)
A3: OBL-002 | B3: Beta Financial Group | C3: Asia | D3: Finance | E3: No | F3: 0.008 | G3: 200 | H3: 0.4 | I3: =NORM.S.INV(F3)
A4: OBL-003 | B4: Gamma Tech Solutions | C4: Asia | D4: Tech | E4: No | F4: 0.02 | G4: 80 | H4: 0.5 | I4: =NORM.S.INV(F4)
A5: OBL-004 | B5: Delta Real Estate | C5: Asia | D5: Real Estate | E5: Yes | F5: 0.03 | G5: 150 | H5: 0.55 | I5: =NORM.S.INV(F5)
A6: OBL-005 | B6: Epsilon Holdings | C6: Asia | D6: Finance | E6: Yes | F6: 0.012 | G6: 180 | H6: 0.4 | I6: =NORM.S.INV(F6)
A7: OBL-006 | B7: Zeta Automobil AG | C7: Europe | D7: Manufacturing | E7: No | F7: 0.01 | G7: 160 | H7: 0.45 | I7: =NORM.S.INV(F7)
A8: OBL-007 | B8: Eta Banque SA | C8: Europe | D8: Finance | E8: No | F8: 0.005 | G8: 250 | H8: 0.35 | I8: =NORM.S.INV(F8)
A9: OBL-008 | B9: Theta PropCo Ltd | C9: Europe | D9: Real Estate | E9: No | F9: 0.025 | G9: 100 | H9: 0.55 | I9: =NORM.S.INV(F9)
A10: OBL-009 | B10: Iota Digital GmbH | C10: Europe | D10: Tech | E10: Yes | F10: 0.018 | G10: 90 | H10: 0.5 | I10: =NORM.S.INV(F10)
A11: OBL-010 | B11: Kappa Energie SA | C11: Europe | D11: Manufacturing | E11: No | F11: 0.007 | G11: 140 | H11: 0.45 | I11: =NORM.S.INV(F11)
A12: OBL-011 | B12: Lambda Capital Corp | C12: Americas | D12: Finance | E12: No | F12: 0.006 | G12: 220 | H12: 0.38 | I12: =NORM.S.INV(F12)
A13: OBL-012 | B13: Mu Semiconductor Inc | C13: Americas | D13: Tech | E13: No | F13: 0.022 | G13: 70 | H13: 0.5 | I13: =NORM.S.INV(F13)
... A16: OBL-015 | B16: Omicron MFG Corp | C16: Americas | D16: Manufacturing | E16: Yes | F16: 0.04 | G16: 60 | H16: 0.48 | I16: =NORM.S.INV(F16)
F18: Total EAD: | G18: =SUM(G2:G16)

Sheet Factors
A1: Factor \ Trial | B1: Trial 1 | C1: Trial 2 | D1: Trial 3 | E1: Trial 4 | F1: Trial 5 | G1: Trial 6 | H1: Trial 7 | I1: Trial 8 | J1: Trial 9 | K1: Trial 10 | L1: Trial 11 | M1: Trial 12 | N1: Trial 13 | O1: Trial 14 | P1: Trial 15 | Q1: Trial 16 | R1: Trial 17 | S1: Trial 18 | T1: Trial 19 | U1: Trial 20 | V1: Trial 21 | W1: Trial 22 | X1: Trial 23 | Y1: Trial 24 | Z1: Trial 25 | AA1: Trial 26 | AB1: Trial 27 | AC1: Trial 28 | AD1: Trial 29 | AE1: Trial 30 | AF1: Trial 31 | AG1: Trial 32 | AH1: Trial 33 | AI1: Trial 34 | AJ1: Trial 35 | AK1: Trial 36 | AL1: Trial 37 | AM1: Trial 38 | AN1: Trial 39 | AO1: Trial 40 | AP1: Trial 41 | AQ1: Trial 42 | AR1: Trial 43 | AS1: Trial 44 | AT1: Trial 45 | AU1: Trial 46 | AV1: Trial 47 | AW1: Trial 48 | AX1: Trial 49 | AY1: Trial 50 | AZ1: Trial 51 | BA1: Trial 52 | BB1: Trial 53 | BC1: Trial 54 | BD1: Trial 55 | BE1: Trial 56 | BF1: Trial 57 | BG1: Trial 58 | BH1: Trial 59 | BI1: Trial 60 | BJ1: Trial 61 | BK1: Trial 62 | BL1: Trial 63 | BM1: Trial 64 | BN1: Trial 65 | BO1: Trial 66 | BP1: Trial 67 | BQ1: Trial 68 | BR1: Trial 69 | BS1: Trial 70 | BT1: Trial 71 | BU1: Trial 72 | BV1: Trial 73 | BW1: Trial 74 | BX1: Trial 75 | BY1: Trial 76 | BZ1: Trial 77 | CA1: Trial 78 | CB1: Trial 79 | CC1: Trial 80 | CD1: Trial 81 | CE1: Trial 82 | CF1: Trial 83 | CG1: Trial 84 | CH1: Trial 85 | CI1: Trial 86 | CJ1: Trial 87 | CK1: Trial 88 | CL1: Trial 89 | CM1: Trial 90 | CN1: Trial 91 | CO1: Trial 92 | CP1: Trial 93 | CQ1: Trial 94 | CR1: Trial 95 | CS1: Trial 96 | CT1: Trial 97 | CU1: Trial 98 | CV1: Trial 99 | CW1: Trial 100 | CX1: Trial 101 | CY1: Trial 102 | CZ1: Trial 103 | DA1: Trial 104 | DB1: Trial 105 | DC1: Trial 106 | DD1: Trial 107 | DE1: Trial 108 | DF1: Trial 109 | DG1: Trial 110 | DH1: Trial 111 | DI1: Trial 112 | DJ1: Trial 113 | DK1: Trial 114 | DL1: Trial 115 | DM1: Trial 116 | DN1: Trial 117 | DO1: Trial 118 | DP1: Trial 119 | DQ1: Trial 120 | DR1: Trial 121 | DS1: Trial 122 | DT1: Trial 123 | DU1: Trial 124 | DV1: Trial 125 | DW1: Trial 126 | DX1: Trial 127 | DY1: Trial 128 | DZ1: Trial 129 | EA1: Trial 130 | EB1: Trial 131 | EC1: Trial 132 | ED1: Trial 133 | EE1: Trial 134 | EF1: Trial 135 | EG1: Trial 136 | EH1: Trial 137 | EI1: Trial 138 | EJ1: Trial 139 | EK1: Trial 140 | EL1: Trial 141 | EM1: Trial 142 | EN1: Trial 143 | EO1: Trial 144 | EP1: Trial 145 | EQ1: Trial 146 | ER1: Trial 147 | ES1: Trial 148 | ET1: Trial 149 | EU1: Trial 150 | EV1: Trial 151 | EW1: Trial 152 | EX1: Trial 153 | EY1: Trial 154 | EZ1: Trial 155 | FA1: Trial 156 | FB1: Trial 157 | FC1: Trial 158 | FD1: Trial 159 | FE1: Trial 160 | FF1: Trial 161 | FG1: Trial 162 | FH1: Trial 163 | FI1: Trial 164 | FJ1: Trial 165 | FK1: Trial 166 | FL1: Trial 167 | FM1: Trial 168 | FN1: Trial 169 | FO1: Trial 170 | FP1: Trial 171 | FQ1: Trial 172 | FR1: Trial 173 | FS1: Trial 174 | FT1: Trial 175 | FU1: Trial 176 | FV1: Trial 177 | FW1: Trial 178 | FX1: Trial 179 | FY1: Trial 180 | FZ1: Trial 181 | GA1: Trial 182 | GB1: Trial 183 | GC1: Trial 184 | GD1: Trial 185 | GE1: Trial 186 | GF1: Trial 187 | GG1: Trial 188 | GH1: Trial 189 | GI1: Trial 190 | GJ1: Trial 191 | GK1: Trial 192 | GL1: Trial 193 | GM1: Trial 194 | GN1: Trial 195 | GO1: Trial 196 | GP1: Trial 197 | GQ1: Trial 198 | GR1: Trial 199 | GS1: Trial 200 | GT1: Trial 201 | GU1: Trial 202 | GV1: Trial 203 | GW1: Trial 204 | GX1: Trial 205 | GY1: Trial 206 | GZ1: Trial 207 | HA1: Trial 208 | HB1: Trial 209 | HC1: Trial 210 | HD1: Trial 211 | HE1: Trial 212 | HF1: Trial 213 | HG1: Trial 214 | HH1: Trial 215 | HI1: Trial 216 | HJ1: Trial 217 | HK1: Trial 218 | HL1: Trial 219 | HM1: Trial 220 | HN1: Trial 221 | HO1: Trial 222 | HP1: Trial 223 | HQ1: Trial 224 | HR1: Trial 225 | HS1: Trial 226 | HT1: Trial 227 | HU1: Trial 228 | HV1: Trial 229 | HW1: Trial 230 | HX1: Trial 231 | HY1: Trial 232 | HZ1: Trial 233 | IA1: Trial 234 | IB1: Trial 235 | IC1: Trial 236 | ID1: Trial 237 | IE1: Trial 238 | IF1: Trial 239 | IG1: Trial 240 | IH1: Trial 241 | II1: Trial 242 | IJ1: Trial 243 | IK1: Trial 244 | IL1: Trial 245 | IM1: Trial 246 | IN1: Trial 247 | IO1: Trial 248 | IP1: Trial 249 | IQ1: Trial 250 | IR1: Trial 251 | IS1: Trial 252 | IT1: Trial 253 | IU1: Trial 254 | IV1: Trial 255 | IW1: Trial 256 | IX1: Trial 257 | IY1: Trial 258 | IZ1: Trial 259 | JA1: Trial 260 | JB1: Trial 261 | JC1: Trial 262 | JD1: Trial 263 | JE1: Trial 264 | JF1: Trial 265 | JG1: Trial 266 | JH1: Trial 267 | JI1: Trial 268 | JJ1: Trial 269 | JK1: Trial 270 | JL1: Trial 271 | JM1: Trial 272 | JN1: Trial 273 | JO1: Trial 274 | JP1: Trial 275 | JQ1: Trial 276 | JR1: Trial 277 | JS1: Trial 278 | JT1: Trial 279 | JU1: Trial 280 | JV1: Trial 281 | JW1: Trial 282 | JX1: Trial 283 | JY1: Trial 284 | JZ1: Trial 285 | KA1: Trial 286 | KB1: Trial 287 | KC1: Trial 288 | KD1: Trial 289 | KE1: Trial 290 | KF1: Trial 291 | KG1: Trial 292 | KH1: Trial 293 | KI1: Trial 294 | KJ1: Trial 295 | KK1: Trial 296 | KL1: Trial 297 | KM1: Trial 298 | KN1: Trial 299 | KO1: Trial 300 | KP1: Trial 301 | KQ1: Trial 302 | KR1: Trial 303 | KS1: Trial 304 | KT1: Trial 305 | KU1: Trial 306 | KV1: Trial 307 | KW1: Trial 308 | KX1: Trial 309 | KY1: Trial 310 | KZ1: Trial 311 | LA1: Trial 312 | LB1: Trial 313 | LC1: Trial 314 | LD1: Trial 315 | LE1: Trial 316 | LF1: Trial 317 | LG1: Trial 318 | LH1: Trial 319 | LI1: Trial 320 | LJ1: Trial 321 | LK1: Trial 322 | LL1: Trial 323 | LM1: Trial 324 | LN1: Trial 325 | LO1: Trial 326 | LP1: Trial 327 | LQ1: Trial 328 | LR1: Trial 329 | LS1: Trial 330 | LT1: Trial 331 | LU1: Trial 332 | LV1: Trial 333 | LW1: Trial 334 | LX1: Trial 335 | LY1: Trial 336 | LZ1: Trial 337 | MA1: Trial 338 | MB1: Trial 339 | MC1: Trial 340 | MD1: Trial 341 | ME1: Trial 342 | MF1: Trial 343 | MG1: Trial 344 | MH1: Trial 345 | MI1: Trial 346 | MJ1: Trial 347 | MK1: Trial 348 | ML1: Trial 349 | MM1: Trial 350 | MN1: Trial 351 | MO1: Trial 352 | MP1: Trial 353 | MQ1: Trial 354 | MR1: Trial 355 | MS1: Trial 356 | MT1: Trial 357 | MU1: Trial 358 | MV1: Trial 359 | MW1: Trial 360 | MX1: Trial 361 | MY1: Trial 362 | MZ1: Trial 363 | NA1: Trial 364 | NB1: Trial 365 | NC1: Trial 366 | ND1: Trial 367 | NE1: Trial 368 | NF1: Trial 369 | NG1: Trial 370 | NH1: Trial 371 | NI1: Trial 372 | NJ1: Trial 373 | NK1: Trial 374 | NL1: Trial 375 | NM1: Trial 376 | NN1: Trial 377 | NO1: Trial 378 | NP1: Trial 379 | NQ1: Trial 380 | NR1: Trial 381 | NS1: Trial 382 | NT1: Trial 383 | NU1: Trial 384 | NV1: Trial 385 | NW1: Trial 386 | NX1: Trial 387 | NY1: Trial 388 | NZ1: Trial 389 | OA1: Trial 390 | OB1: Trial 391 | OC1: Trial 392 | OD1: Trial 393 | OE1: Trial 394 | OF1: Trial 395 | OG1: Trial 396 | OH1: Trial 397 | OI1: Trial 398 | OJ1: Trial 399 | OK1: Trial 400 | OL1: Trial 401 | OM1: Trial 402 | ON1: Trial 403 | OO1: Trial 404 | OP1: Trial 405 | OQ1: Trial 406 | OR1: Trial 407 | OS1: Trial 408 | OT1: Trial 409 | OU1: Trial 410 | OV1: Trial 411 | OW1: Trial 412 | OX1: Trial 413 | OY1: Trial 414 | OZ1: Trial 415 | PA1: Trial 416 | PB1: Trial 417 | PC1: Trial 418 | PD1: Trial 419 | PE1: Trial 420 | PF1: Trial 421 | PG1: Trial 422 | PH1: Trial 423 | PI1: Trial 424 | PJ1: Trial 425 | PK1: Trial 426 | PL1: Trial 427 | PM1: Trial 428 | PN1: Trial 429 | PO1: Trial 430 | PP1: Trial 431 | PQ1: Trial 432 | PR1: Trial 433 | PS1: Trial 434 | PT1: Trial 435 | PU1: Trial 436 | PV1: Trial 437 | PW1: Trial 438 | PX1: Trial 439 | PY1: Trial 440 | PZ1: Trial 441 | QA1: Trial 442 | QB1: Trial 443 | QC1: Trial 444 | QD1: Trial 445 | QE1: Trial 446 | QF1: Trial 447 | QG1: Trial 448 | QH1: Trial 449 | QI1: Trial 450 | QJ1: Trial 451 | QK1: Trial 452 | QL1: Trial 453 | QM1: Trial 454 | QN1: Trial 455 | QO1: Trial 456 | QP1: Trial 457 | QQ1: Trial 458 | QR1: Trial 459 | QS1: Trial 460 | QT1: Trial 461 | QU1: Trial 462 | QV1: Trial 463 | QW1: Trial 464 | QX1: Trial 465 | QY1: Trial 466 | QZ1: Trial 467 | RA1: Trial 468 | RB1: Trial 469 | RC1: Trial 470 | RD1: Trial 471 | RE1: Trial 472 | RF1: Trial 473 | RG1: Trial 474 | RH1: Trial 475 | RI1: Trial 476 | RJ1: Trial 477 | RK1: Trial 478 | RL1: Trial 479 | RM1: Trial 480 | RN1: Trial 481 | RO1: Trial 482 | RP1: Trial 483 | RQ1: Trial 484 | RR1: Trial 485 | RS1: Trial 486 | RT1: Trial 487 | RU1: Trial 488 | RV1: Trial 489 | RW1: Trial 490 | RX1: Trial 491 | RY1: Trial 492 | RZ1: Trial 493 | SA1: Trial 494 | SB1: Trial 495 | SC1: Trial 496 | SD1: Trial 497 | SE1: Trial 498 | SF1: Trial 499 | SG1: Trial 500
A2: Region: Asia | B2: =NORM.S.INV(RAND()) | C2: =NORM.S.INV(RAND()) | D2: =NORM.S.INV(RAND()) | E2: =NORM.S.INV(RAND()) | F2: =NORM.S.INV(RAND()) | G2: =NORM.S.INV(RAND()) | H2: =NORM.S.INV(RAND()) | I2: =NORM.S.INV(RAND()) | ... SG2: =NORM.S.INV(RAND())
A3: Region: Europe | B3: =NORM.S.INV(RAND()) | C3: =NORM.S.INV(RAND()) | D3: =NORM.S.INV(RAND()) | E3: =NORM.S.INV(RAND()) | F3: =NORM.S.INV(RAND()) | G3: =NORM.S.INV(RAND()) | H3: =NORM.S.INV(RAND()) | I3: =NORM.S.INV(RAND()) | ... SG3: =NORM.S.INV(RAND())
A4: Region: Americas | B4: =NORM.S.INV(RAND()) | C4: =NORM.S.INV(RAND()) | D4: =NORM.S.INV(RAND()) | E4: =NORM.S.INV(RAND()) | F4: =NORM.S.INV(RAND()) | G4: =NORM.S.INV(RAND()) | H4: =NORM.S.INV(RAND()) | I4: =NORM.S.INV(RAND()) | ... SG4: =NORM.S.INV(RAND())
A5: Sector: Finance | B5: =NORM.S.INV(RAND()) | C5: =NORM.S.INV(RAND()) | D5: =NORM.S.INV(RAND()) | E5: =NORM.S.INV(RAND()) | F5: =NORM.S.INV(RAND()) | G5: =NORM.S.INV(RAND()) | H5: =NORM.S.INV(RAND()) | I5: =NORM.S.INV(RAND()) | ... SG5: =NORM.S.INV(RAND())
A6: Sector: Manufacturing | B6: =NORM.S.INV(RAND()) | C6: =NORM.S.INV(RAND()) | D6: =NORM.S.INV(RAND()) | E6: =NORM.S.INV(RAND()) | F6: =NORM.S.INV(RAND()) | G6: =NORM.S.INV(RAND()) | H6: =NORM.S.INV(RAND()) | I6: =NORM.S.INV(RAND()) | ... SG6: =NORM.S.INV(RAND())
A7: Sector: Tech | B7: =NORM.S.INV(RAND()) | C7: =NORM.S.INV(RAND()) | D7: =NORM.S.INV(RAND()) | E7: =NORM.S.INV(RAND()) | F7: =NORM.S.INV(RAND()) | G7: =NORM.S.INV(RAND()) | H7: =NORM.S.INV(RAND()) | I7: =NORM.S.INV(RAND()) | ... SG7: =NORM.S.INV(RAND())
A8: Sector: Real Estate | B8: =NORM.S.INV(RAND()) | C8: =NORM.S.INV(RAND()) | D8: =NORM.S.INV(RAND()) | E8: =NORM.S.INV(RAND()) | F8: =NORM.S.INV(RAND()) | G8: =NORM.S.INV(RAND()) | H8: =NORM.S.INV(RAND()) | I8: =NORM.S.INV(RAND()) | ... SG8: =NORM.S.INV(RAND())
A9: HNWI: No | B9: =NORM.S.INV(RAND()) | C9: =NORM.S.INV(RAND()) | D9: =NORM.S.INV(RAND()) | E9: =NORM.S.INV(RAND()) | F9: =NORM.S.INV(RAND()) | G9: =NORM.S.INV(RAND()) | H9: =NORM.S.INV(RAND()) | I9: =NORM.S.INV(RAND()) | ... SG9: =NORM.S.INV(RAND())
A10: HNWI: Yes | B10: =NORM.S.INV(RAND()) | C10: =NORM.S.INV(RAND()) | D10: =NORM.S.INV(RAND()) | E10: =NORM.S.INV(RAND()) | F10: =NORM.S.INV(RAND()) | G10: =NORM.S.INV(RAND()) | H10: =NORM.S.INV(RAND()) | I10: =NORM.S.INV(RAND()) | ... SG10: =NORM.S.INV(RAND())

Sheet Simulation
A1: Obligor \ Trial | B1: Trial 1 | C1: Trial 2 | D1: Trial 3 | E1: Trial 4 | F1: Trial 5 | G1: Trial 6 | H1: Trial 7 | I1: Trial 8 | J1: Trial 9 | K1: Trial 10 | L1: Trial 11 | M1: Trial 12 | N1: Trial 13 | O1: Trial 14 | P1: Trial 15 | Q1: Trial 16 | R1: Trial 17 | S1: Trial 18 | T1: Trial 19 | U1: Trial 20 | V1: Trial 21 | W1: Trial 22 | X1: Trial 23 | Y1: Trial 24 | Z1: Trial 25 | AA1: Trial 26 | AB1: Trial 27 | AC1: Trial 28 | AD1: Trial 29 | AE1: Trial 30 | AF1: Trial 31 | AG1: Trial 32 | AH1: Trial 33 | AI1: Trial 34 | AJ1: Trial 35 | AK1: Trial 36 | AL1: Trial 37 | AM1: Trial 38 | AN1: Trial 39 | AO1: Trial 40 | AP1: Trial 41 | AQ1: Trial 42 | AR1: Trial 43 | AS1: Trial 44 | AT1: Trial 45 | AU1: Trial 46 | AV1: Trial 47 | AW1: Trial 48 | AX1: Trial 49 | AY1: Trial 50 | AZ1: Trial 51 | BA1: Trial 52 | BB1: Trial 53 | BC1: Trial 54 | BD1: Trial 55 | BE1: Trial 56 | BF1: Trial 57 | BG1: Trial 58 | BH1: Trial 59 | BI1: Trial 60 | BJ1: Trial 61 | BK1: Trial 62 | BL1: Trial 63 | BM1: Trial 64 | BN1: Trial 65 | BO1: Trial 66 | BP1: Trial 67 | BQ1: Trial 68 | BR1: Trial 69 | BS1: Trial 70 | BT1: Trial 71 | BU1: Trial 72 | BV1: Trial 73 | BW1: Trial 74 | BX1: Trial 75 | BY1: Trial 76 | BZ1: Trial 77 | CA1: Trial 78 | CB1: Trial 79 | CC1: Trial 80 | CD1: Trial 81 | CE1: Trial 82 | CF1: Trial 83 | CG1: Trial 84 | CH1: Trial 85 | CI1: Trial 86 | CJ1: Trial 87 | CK1: Trial 88 | CL1: Trial 89 | CM1: Trial 90 | CN1: Trial 91 | CO1: Trial 92 | CP1: Trial 93 | CQ1: Trial 94 | CR1: Trial 95 | CS1: Trial 96 | CT1: Trial 97 | CU1: Trial 98 | CV1: Trial 99 | CW1: Trial 100 | CX1: Trial 101 | CY1: Trial 102 | CZ1: Trial 103 | DA1: Trial 104 | DB1: Trial 105 | DC1: Trial 106 | DD1: Trial 107 | DE1: Trial 108 | DF1: Trial 109 | DG1: Trial 110 | DH1: Trial 111 | DI1: Trial 112 | DJ1: Trial 113 | DK1: Trial 114 | DL1: Trial 115 | DM1: Trial 116 | DN1: Trial 117 | DO1: Trial 118 | DP1: Trial 119 | DQ1: Trial 120 | DR1: Trial 121 | DS1: Trial 122 | DT1: Trial 123 | DU1: Trial 124 | DV1: Trial 125 | DW1: Trial 126 | DX1: Trial 127 | DY1: Trial 128 | DZ1: Trial 129 | EA1: Trial 130 | EB1: Trial 131 | EC1: Trial 132 | ED1: Trial 133 | EE1: Trial 134 | EF1: Trial 135 | EG1: Trial 136 | EH1: Trial 137 | EI1: Trial 138 | EJ1: Trial 139 | EK1: Trial 140 | EL1: Trial 141 | EM1: Trial 142 | EN1: Trial 143 | EO1: Trial 144 | EP1: Trial 145 | EQ1: Trial 146 | ER1: Trial 147 | ES1: Trial 148 | ET1: Trial 149 | EU1: Trial 150 | EV1: Trial 151 | EW1: Trial 152 | EX1: Trial 153 | EY1: Trial 154 | EZ1: Trial 155 | FA1: Trial 156 | FB1: Trial 157 | FC1: Trial 158 | FD1: Trial 159 | FE1: Trial 160 | FF1: Trial 161 | FG1: Trial 162 | FH1: Trial 163 | FI1: Trial 164 | FJ1: Trial 165 | FK1: Trial 166 | FL1: Trial 167 | FM1: Trial 168 | FN1: Trial 169 | FO1: Trial 170 | FP1: Trial 171 | FQ1: Trial 172 | FR1: Trial 173 | FS1: Trial 174 | FT1: Trial 175 | FU1: Trial 176 | FV1: Trial 177 | FW1: Trial 178 | FX1: Trial 179 | FY1: Trial 180 | FZ1: Trial 181 | GA1: Trial 182 | GB1: Trial 183 | GC1: Trial 184 | GD1: Trial 185 | GE1: Trial 186 | GF1: Trial 187 | GG1: Trial 188 | GH1: Trial 189 | GI1: Trial 190 | GJ1: Trial 191 | GK1: Trial 192 | GL1: Trial 193 | GM1: Trial 194 | GN1: Trial 195 | GO1: Trial 196 | GP1: Trial 197 | GQ1: Trial 198 | GR1: Trial 199 | GS1: Trial 200 | GT1: Trial 201 | GU1: Trial 202 | GV1: Trial 203 | GW1: Trial 204 | GX1: Trial 205 | GY1: Trial 206 | GZ1: Trial 207 | HA1: Trial 208 | HB1: Trial 209 | HC1: Trial 210 | HD1: Trial 211 | HE1: Trial 212 | HF1: Trial 213 | HG1: Trial 214 | HH1: Trial 215 | HI1: Trial 216 | HJ1: Trial 217 | HK1: Trial 218 | HL1: Trial 219 | HM1: Trial 220 | HN1: Trial 221 | HO1: Trial 222 | HP1: Trial 223 | HQ1: Trial 224 | HR1: Trial 225 | HS1: Trial 226 | HT1: Trial 227 | HU1: Trial 228 | HV1: Trial 229 | HW1: Trial 230 | HX1: Trial 231 | HY1: Trial 232 | HZ1: Trial 233 | IA1: Trial 234 | IB1: Trial 235 | IC1: Trial 236 | ID1: Trial 237 | IE1: Trial 238 | IF1: Trial 239 | IG1: Trial 240 | IH1: Trial 241 | II1: Trial 242 | IJ1: Trial 243 | IK1: Trial 244 | IL1: Trial 245 | IM1: Trial 246 | IN1: Trial 247 | IO1: Trial 248 | IP1: Trial 249 | IQ1: Trial 250 | IR1: Trial 251 | IS1: Trial 252 | IT1: Trial 253 | IU1: Trial 254 | IV1: Trial 255 | IW1: Trial 256 | IX1: Trial 257 | IY1: Trial 258 | IZ1: Trial 259 | JA1: Trial 260 | JB1: Trial 261 | JC1: Trial 262 | JD1: Trial 263 | JE1: Trial 264 | JF1: Trial 265 | JG1: Trial 266 | JH1: Trial 267 | JI1: Trial 268 | JJ1: Trial 269 | JK1: Trial 270 | JL1: Trial 271 | JM1: Trial 272 | JN1: Trial 273 | JO1: Trial 274 | JP1: Trial 275 | JQ1: Trial 276 | JR1: Trial 277 | JS1: Trial 278 | JT1: Trial 279 | JU1: Trial 280 | JV1: Trial 281 | JW1: Trial 282 | JX1: Trial 283 | JY1: Trial 284 | JZ1: Trial 285 | KA1: Trial 286 | KB1: Trial 287 | KC1: Trial 288 | KD1: Trial 289 | KE1: Trial 290 | KF1: Trial 291 | KG1: Trial 292 | KH1: Trial 293 | KI1: Trial 294 | KJ1: Trial 295 | KK1: Trial 296 | KL1: Trial 297 | KM1: Trial 298 | KN1: Trial 299 | KO1: Trial 300 | KP1: Trial 301 | KQ1: Trial 302 | KR1: Trial 303 | KS1: Trial 304 | KT1: Trial 305 | KU1: Trial 306 | KV1: Trial 307 | KW1: Trial 308 | KX1: Trial 309 | KY1: Trial 310 | KZ1: Trial 311 | LA1: Trial 312 | LB1: Trial 313 | LC1: Trial 314 | LD1: Trial 315 | LE1: Trial 316 | LF1: Trial 317 | LG1: Trial 318 | LH1: Trial 319 | LI1: Trial 320 | LJ1: Trial 321 | LK1: Trial 322 | LL1: Trial 323 | LM1: Trial 324 | LN1: Trial 325 | LO1: Trial 326 | LP1: Trial 327 | LQ1: Trial 328 | LR1: Trial 329 | LS1: Trial 330 | LT1: Trial 331 | LU1: Trial 332 | LV1: Trial 333 | LW1: Trial 334 | LX1: Trial 335 | LY1: Trial 336 | LZ1: Trial 337 | MA1: Trial 338 | MB1: Trial 339 | MC1: Trial 340 | MD1: Trial 341 | ME1: Trial 342 | MF1: Trial 343 | MG1: Trial 344 | MH1: Trial 345 | MI1: Trial 346 | MJ1: Trial 347 | MK1: Trial 348 | ML1: Trial 349 | MM1: Trial 350 | MN1: Trial 351 | MO1: Trial 352 | MP1: Trial 353 | MQ1: Trial 354 | MR1: Trial 355 | MS1: Trial 356 | MT1: Trial 357 | MU1: Trial 358 | MV1: Trial 359 | MW1: Trial 360 | MX1: Trial 361 | MY1: Trial 362 | MZ1: Trial 363 | NA1: Trial 364 | NB1: Trial 365 | NC1: Trial 366 | ND1: Trial 367 | NE1: Trial 368 | NF1: Trial 369 | NG1: Trial 370 | NH1: Trial 371 | NI1: Trial 372 | NJ1: Trial 373 | NK1: Trial 374 | NL1: Trial 375 | NM1: Trial 376 | NN1: Trial 377 | NO1: Trial 378 | NP1: Trial 379 | NQ1: Trial 380 | NR1: Trial 381 | NS1: Trial 382 | NT1: Trial 383 | NU1: Trial 384 | NV1: Trial 385 | NW1: Trial 386 | NX1: Trial 387 | NY1: Trial 388 | NZ1: Trial 389 | OA1: Trial 390 | OB1: Trial 391 | OC1: Trial 392 | OD1: Trial 393 | OE1: Trial 394 | OF1: Trial 395 | OG1: Trial 396 | OH1: Trial 397 | OI1: Trial 398 | OJ1: Trial 399 | OK1: Trial 400 | OL1: Trial 401 | OM1: Trial 402 | ON1: Trial 403 | OO1: Trial 404 | OP1: Trial 405 | OQ1: Trial 406 | OR1: Trial 407 | OS1: Trial 408 | OT1: Trial 409 | OU1: Trial 410 | OV1: Trial 411 | OW1: Trial 412 | OX1: Trial 413 | OY1: Trial 414 | OZ1: Trial 415 | PA1: Trial 416 | PB1: Trial 417 | PC1: Trial 418 | PD1: Trial 419 | PE1: Trial 420 | PF1: Trial 421 | PG1: Trial 422 | PH1: Trial 423 | PI1: Trial 424 | PJ1: Trial 425 | PK1: Trial 426 | PL1: Trial 427 | PM1: Trial 428 | PN1: Trial 429 | PO1: Trial 430 | PP1: Trial 431 | PQ1: Trial 432 | PR1: Trial 433 | PS1: Trial 434 | PT1: Trial 435 | PU1: Trial 436 | PV1: Trial 437 | PW1: Trial 438 | PX1: Trial 439 | PY1: Trial 440 | PZ1: Trial 441 | QA1: Trial 442 | QB1: Trial 443 | QC1: Trial 444 | QD1: Trial 445 | QE1: Trial 446 | QF1: Trial 447 | QG1: Trial 448 | QH1: Trial 449 | QI1: Trial 450 | QJ1: Trial 451 | QK1: Trial 452 | QL1: Trial 453 | QM1: Trial 454 | QN1: Trial 455 | QO1: Trial 456 | QP1: Trial 457 | QQ1: Trial 458 | QR1: Trial 459 | QS1: Trial 460 | QT1: Trial 461 | QU1: Trial 462 | QV1: Trial 463 | QW1: Trial 464 | QX1: Trial 465 | QY1: Trial 466 | QZ1: Trial 467 | RA1: Trial 468 | RB1: Trial 469 | RC1: Trial 470 | RD1: Trial 471 | RE1: Trial 472 | RF1: Trial 473 | RG1: Trial 474 | RH1: Trial 475 | RI1: Trial 476 | RJ1: Trial 477 | RK1: Trial 478 | RL1: Trial 479 | RM1: Trial 480 | RN1: Trial 481 | RO1: Trial 482 | RP1: Trial 483 | RQ1: Trial 484 | RR1: Trial 485 | RS1: Trial 486 | RT1: Trial 487 | RU1: Trial 488 | RV1: Trial 489 | RW1: Trial 490 | RX1: Trial 491 | RY1: Trial 492 | RZ1: Trial 493 | SA1: Trial 494 | SB1: Trial 495 | SC1: Trial 496 | SD1: Trial 497 | SE1: Trial 498 | SF1: Trial 499 | SG1: Trial 500
A2: OBL-001 | B2: =SQRT(Parameters!$B$5)*Factors!B2+SQRT(Parameters!$B$6)*Factors!B6+SQRT(Parameters!$B$7)*Factors!B9+SQRT(Parameters!$B$9)*NORM.S.INV(RAND()) | C2: =SQRT(Parameters!$B$5)*Factors!C2+SQRT(Parameters!$B$6)*Factors!C6+SQRT(Parameters!$B$7)*Factors!C9+SQRT(Parameters!$B$9)*NORM.S.INV(RAND()) | D2: =SQRT(Parameters!$B$5)*Factors!D2+SQRT(Parameters!$B$6)*Factors!D6+SQRT(Parameters!$B$7)*Factors!D9+SQRT(Parameters!$B$9)*NORM.S.INV(RAND()) | E2: =SQRT(Parameters!$B$5)*Factors!E2+SQRT(Parameters!$B$6)*Factors!E6+SQRT(Parameters!$B$7)*Factors!E9+SQRT(Parameters!$B$9)*NORM.S.INV(RAND()) | F2: =SQRT(Parameters!$B$5)*Factors!F2+SQRT(Parameters!$B$6)*Factors!F6+SQRT(Parameters!$B$7)*Factors!F9+SQRT(Parameters!$B$9)*NORM.S.INV(RAND()) | G2: =SQRT(Parameters!$B$5)*Factors!G2+SQRT(Parameters!$B$6)*Factors!G6+SQRT(Parameters!$B$7)*Factors!G9+SQRT(Parameters!$B$9)*NORM.S.INV(RAND()) | H2: =SQRT(Parameters!$B$5)*Factors!H2+SQRT(Parameters!$B$6)*Factors!H6+SQRT(Parameters!$B$7)*Factors!H9+SQRT(Parameters!$B$9)*NORM.S.INV(RAND()) | I2: =SQRT(Parameters!$B$5)*Factors!I2+SQRT(Parameters!$B$6)*Factors!I6+SQRT(Parameters!$B$7)*Factors!I9+SQRT(Parameters!$B$9)*NORM.S.INV(RAND()) | ... SG2: =SQRT(Parameters!$B$5)*Factors!SG2+SQRT(Parameters!$B$6)*Factors!SG6+SQRT(Parameters!$B$7)*Factors!SG9+SQRT(Parameters!$B$9)*NORM.S.INV(RAND())
A3: OBL-002 | B3: =SQRT(Parameters!$B$5)*Factors!B2+SQRT(Parameters!$B$6)*Factors!B5+SQRT(Parameters!$B$7)*Factors!B9+SQRT(Parameters!$B$9)*NORM.S.INV(RAND()) | C3: =SQRT(Parameters!$B$5)*Factors!C2+SQRT(Parameters!$B$6)*Factors!C5+SQRT(Parameters!$B$7)*Factors!C9+SQRT(Parameters!$B$9)*NORM.S.INV(RAND()) | D3: =SQRT(Parameters!$B$5)*Factors!D2+SQRT(Parameters!$B$6)*Factors!D5+SQRT(Parameters!$B$7)*Factors!D9+SQRT(Parameters!$B$9)*NORM.S.INV(RAND()) | E3: =SQRT(Parameters!$B$5)*Factors!E2+SQRT(Parameters!$B$6)*Factors!E5+SQRT(Parameters!$B$7)*Factors!E9+SQRT(Parameters!$B$9)*NORM.S.INV(RAND()) | F3: =SQRT(Parameters!$B$5)*Factors!F2+SQRT(Parameters!$B$6)*Factors!F5+SQRT(Parameters!$B$7)*Factors!F9+SQRT(Parameters!$B$9)*NORM.S.INV(RAND()) | G3: =SQRT(Parameters!$B$5)*Factors!G2+SQRT(Parameters!$B$6)*Factors!G5+SQRT(Parameters!$B$7)*Factors!G9+SQRT(Parameters!$B$9)*NORM.S.INV(RAND()) | H3: =SQRT(Parameters!$B$5)*Factors!H2+SQRT(Parameters!$B$6)*Factors!H5+SQRT(Parameters!$B$7)*Factors!H9+SQRT(Parameters!$B$9)*NORM.S.INV(RAND()) | I3: =SQRT(Parameters!$B$5)*Factors!I2+SQRT(Parameters!$B$6)*Factors!I5+SQRT(Parameters!$B$7)*Factors!I9+SQRT(Parameters!$B$9)*NORM.S.INV(RAND()) | ... SG3: =SQRT(Parameters!$B$5)*Factors!SG2+SQRT(Parameters!$B$6)*Factors!SG5+SQRT(Parameters!$B$7)*Factors!SG9+SQRT(Parameters!$B$9)*NORM.S.INV(RAND())
A4: OBL-003 | B4: =SQRT(Parameters!$B$5)*Factors!B2+SQRT(Parameters!$B$6)*Factors!B7+SQRT(Parameters!$B$7)*Factors!B9+SQRT(Parameters!$B$9)*NORM.S.INV(RAND()) | C4: =SQRT(Parameters!$B$5)*Factors!C2+SQRT(Parameters!$B$6)*Factors!C7+SQRT(Parameters!$B$7)*Factors!C9+SQRT(Parameters!$B$9)*NORM.S.INV(RAND()) | D4: =SQRT(Parameters!$B$5)*Factors!D2+SQRT(Parameters!$B$6)*Factors!D7+SQRT(Parameters!$B$7)*Factors!D9+SQRT(Parameters!$B$9)*NORM.S.INV(RAND()) | E4: =SQRT(Parameters!$B$5)*Factors!E2+SQRT(Parameters!$B$6)*Factors!E7+SQRT(Parameters!$B$7)*Factors!E9+SQRT(Parameters!$B$9)*NORM.S.INV(RAND()) | F4: =SQRT(Parameters!$B$5)*Factors!F2+SQRT(Parameters!$B$6)*Factors!F7+SQRT(Parameters!$B$7)*Factors!F9+SQRT(Parameters!$B$9)*NORM.S.INV(RAND()) | G4: =SQRT(Parameters!$B$5)*Factors!G2+SQRT(Parameters!$B$6)*Factors!G7+SQRT(Parameters!$B$7)*Factors!G9+SQRT(Parameters!$B$9)*NORM.S.INV(RAND()) | H4: =SQRT(Parameters!$B$5)*Factors!H2+SQRT(Parameters!$B$6)*Factors!H7+SQRT(Parameters!$B$7)*Factors!H9+SQRT(Parameters!$B$9)*NORM.S.INV(RAND()) | I4: =SQRT(Parameters!$B$5)*Factors!I2+SQRT(Parameters!$B$6)*Factors!I7+SQRT(Parameters!$B$7)*Factors!I9+SQRT(Parameters!$B$9)*NORM.S.INV(RAND()) | ... SG4: =SQRT(Parameters!$B$5)*Factors!SG2+SQRT(Parameters!$B$6)*Factors!SG7+SQRT(Parameters!$B$7)*Factors!SG9+SQRT(Parameters!$B$9)*NORM.S.INV(RAND())
A5: OBL-004 | B5: =SQRT(Parameters!$B$5)*Factors!B2+SQRT(Parameters!$B$6)*Factors!B8+SQRT(Parameters!$B$7)*Factors!B10+SQRT(Parameters!$B$9)*NORM.S.INV(RAND()) | C5: =SQRT(Parameters!$B$5)*Factors!C2+SQRT(Parameters!$B$6)*Factors!C8+SQRT(Parameters!$B$7)*Factors!C10+SQRT(Parameters!$B$9)*NORM.S.INV(RAND()) | D5: =SQRT(Parameters!$B$5)*Factors!D2+SQRT(Parameters!$B$6)*Factors!D8+SQRT(Parameters!$B$7)*Factors!D10+SQRT(Parameters!$B$9)*NORM.S.INV(RAND()) | E5: =SQRT(Parameters!$B$5)*Factors!E2+SQRT(Parameters!$B$6)*Factors!E8+SQRT(Parameters!$B$7)*Factors!E10+SQRT(Parameters!$B$9)*NORM.S.INV(RAND()) | F5: =SQRT(Parameters!$B$5)*Factors!F2+SQRT(Parameters!$B$6)*Factors!F8+SQRT(Parameters!$B$7)*Factors!F10+SQRT(Parameters!$B$9)*NORM.S.INV(RAND()) | G5: =SQRT(Parameters!$B$5)*Factors!G2+SQRT(Parameters!$B$6)*Factors!G8+SQRT(Parameters!$B$7)*Factors!G10+SQRT(Parameters!$B$9)*NORM.S.INV(RAND()) | H5: =SQRT(Parameters!$B$5)*Factors!H2+SQRT(Parameters!$B$6)*Factors!H8+SQRT(Parameters!$B$7)*Factors!H10+SQRT(Parameters!$B$9)*NORM.S.INV(RAND()) | I5: =SQRT(Parameters!$B$5)*Factors!I2+SQRT(Parameters!$B$6)*Factors!I8+SQRT(Parameters!$B$7)*Factors!I10+SQRT(Parameters!$B$9)*NORM.S.INV(RAND()) | ... SG5: =SQRT(Parameters!$B$5)*Factors!SG2+SQRT(Parameters!$B$6)*Factors!SG8+SQRT(Parameters!$B$7)*Factors!SG10+SQRT(Parameters!$B$9)*NORM.S.INV(RAND())
A6: OBL-005 | B6: =SQRT(Parameters!$B$5)*Factors!B2+SQRT(Parameters!$B$6)*Factors!B5+SQRT(Parameters!$B$7)*Factors!B10+SQRT(Parameters!$B$9)*NORM.S.INV(RAND()) | C6: =SQRT(Parameters!$B$5)*Factors!C2+SQRT(Parameters!$B$6)*Factors!C5+SQRT(Parameters!$B$7)*Factors!C10+SQRT(Parameters!$B$9)*NORM.S.INV(RAND()) | D6: =SQRT(Parameters!$B$5)*Factors!D2+SQRT(Parameters!$B$6)*Factors!D5+SQRT(Parameters!$B$7)*Factors!D10+SQRT(Parameters!$B$9)*NORM.S.INV(RAND()) | E6: =SQRT(Parameters!$B$5)*Factors!E2+SQRT(Parameters!$B$6)*Factors!E5+SQRT(Parameters!$B$7)*Factors!E10+SQRT(Parameters!$B$9)*NORM.S.INV(RAND()) | F6: =SQRT(Parameters!$B$5)*Factors!F2+SQRT(Parameters!$B$6)*Factors!F5+SQRT(Parameters!$B$7)*Factors!F10+SQRT(Parameters!$B$9)*NORM.S.INV(RAND()) | G6: =SQRT(Parameters!$B$5)*Factors!G2+SQRT(Parameters!$B$6)*Factors!G5+SQRT(Parameters!$B$7)*Factors!G10+SQRT(Parameters!$B$9)*NORM.S.INV(RAND()) | H6: =SQRT(Parameters!$B$5)*Factors!H2+SQRT(Parameters!$B$6)*Factors!H5+SQRT(Parameters!$B$7)*Factors!H10+SQRT(Parameters!$B$9)*NORM.S.INV(RAND()) | I6: =SQRT(Parameters!$B$5)*Factors!I2+SQRT(Parameters!$B$6)*Factors!I5+SQRT(Parameters!$B$7)*Factors!I10+SQRT(Parameters!$B$9)*NORM.S.INV(RAND()) | ... SG6: =SQRT(Parameters!$B$5)*Factors!SG2+SQRT(Parameters!$B$6)*Factors!SG5+SQRT(Parameters!$B$7)*Factors!SG10+SQRT(Parameters!$B$9)*NORM.S.INV(RAND())
A7: OBL-006 | B7: =SQRT(Parameters!$B$5)*Factors!B3+SQRT(Parameters!$B$6)*Factors!B6+SQRT(Parameters!$B$7)*Factors!B9+SQRT(Parameters!$B$9)*NORM.S.INV(RAND()) | C7: =SQRT(Parameters!$B$5)*Factors!C3+SQRT(Parameters!$B$6)*Factors!C6+SQRT(Parameters!$B$7)*Factors!C9+SQRT(Parameters!$B$9)*NORM.S.INV(RAND()) | D7: =SQRT(Parameters!$B$5)*Factors!D3+SQRT(Parameters!$B$6)*Factors!D6+SQRT(Parameters!$B$7)*Factors!D9+SQRT(Parameters!$B$9)*NORM.S.INV(RAND()) | E7: =SQRT(Parameters!$B$5)*Factors!E3+SQRT(Parameters!$B$6)*Factors!E6+SQRT(Parameters!$B$7)*Factors!E9+SQRT(Parameters!$B$9)*NORM.S.INV(RAND()) | F7: =SQRT(Parameters!$B$5)*Factors!F3+SQRT(Parameters!$B$6)*Factors!F6+SQRT(Parameters!$B$7)*Factors!F9+SQRT(Parameters!$B$9)*NORM.S.INV(RAND()) | G7: =SQRT(Parameters!$B$5)*Factors!G3+SQRT(Parameters!$B$6)*Factors!G6+SQRT(Parameters!$B$7)*Factors!G9+SQRT(Parameters!$B$9)*NORM.S.INV(RAND()) | H7: =SQRT(Parameters!$B$5)*Factors!H3+SQRT(Parameters!$B$6)*Factors!H6+SQRT(Parameters!$B$7)*Factors!H9+SQRT(Parameters!$B$9)*NORM.S.INV(RAND()) | I7: =SQRT(Parameters!$B$5)*Factors!I3+SQRT(Parameters!$B$6)*Factors!I6+SQRT(Parameters!$B$7)*Factors!I9+SQRT(Parameters!$B$9)*NORM.S.INV(RAND()) | ... SG7: =SQRT(Parameters!$B$5)*Factors!SG3+SQRT(Parameters!$B$6)*Factors!SG6+SQRT(Parameters!$B$7)*Factors!SG9+SQRT(Parameters!$B$9)*NORM.S.INV(RAND())
A8: OBL-007 | B8: =SQRT(Parameters!$B$5)*Factors!B3+SQRT(Parameters!$B$6)*Factors!B5+SQRT(Parameters!$B$7)*Factors!B9+SQRT(Parameters!$B$9)*NORM.S.INV(RAND()) | C8: =SQRT(Parameters!$B$5)*Factors!C3+SQRT(Parameters!$B$6)*Factors!C5+SQRT(Parameters!$B$7)*Factors!C9+SQRT(Parameters!$B$9)*NORM.S.INV(RAND()) | D8: =SQRT(Parameters!$B$5)*Factors!D3+SQRT(Parameters!$B$6)*Factors!D5+SQRT(Parameters!$B$7)*Factors!D9+SQRT(Parameters!$B$9)*NORM.S.INV(RAND()) | E8: =SQRT(Parameters!$B$5)*Factors!E3+SQRT(Parameters!$B$6)*Factors!E5+SQRT(Parameters!$B$7)*Factors!E9+SQRT(Parameters!$B$9)*NORM.S.INV(RAND()) | F8: =SQRT(Parameters!$B$5)*Factors!F3+SQRT(Parameters!$B$6)*Factors!F5+SQRT(Parameters!$B$7)*Factors!F9+SQRT(Parameters!$B$9)*NORM.S.INV(RAND()) | G8: =SQRT(Parameters!$B$5)*Factors!G3+SQRT(Parameters!$B$6)*Factors!G5+SQRT(Parameters!$B$7)*Factors!G9+SQRT(Parameters!$B$9)*NORM.S.INV(RAND()) | H8: =SQRT(Parameters!$B$5)*Factors!H3+SQRT(Parameters!$B$6)*Factors!H5+SQRT(Parameters!$B$7)*Factors!H9+SQRT(Parameters!$B$9)*NORM.S.INV(RAND()) | I8: =SQRT(Parameters!$B$5)*Factors!I3+SQRT(Parameters!$B$6)*Factors!I5+SQRT(Parameters!$B$7)*Factors!I9+SQRT(Parameters!$B$9)*NORM.S.INV(RAND()) | ... SG8: =SQRT(Parameters!$B$5)*Factors!SG3+SQRT(Parameters!$B$6)*Factors!SG5+SQRT(Parameters!$B$7)*Factors!SG9+SQRT(Parameters!$B$9)*NORM.S.INV(RAND())
A9: OBL-008 | B9: =SQRT(Parameters!$B$5)*Factors!B3+SQRT(Parameters!$B$6)*Factors!B8+SQRT(Parameters!$B$7)*Factors!B9+SQRT(Parameters!$B$9)*NORM.S.INV(RAND()) | C9: =SQRT(Parameters!$B$5)*Factors!C3+SQRT(Parameters!$B$6)*Factors!C8+SQRT(Parameters!$B$7)*Factors!C9+SQRT(Parameters!$B$9)*NORM.S.INV(RAND()) | D9: =SQRT(Parameters!$B$5)*Factors!D3+SQRT(Parameters!$B$6)*Factors!D8+SQRT(Parameters!$B$7)*Factors!D9+SQRT(Parameters!$B$9)*NORM.S.INV(RAND()) | E9: =SQRT(Parameters!$B$5)*Factors!E3+SQRT(Parameters!$B$6)*Factors!E8+SQRT(Parameters!$B$7)*Factors!E9+SQRT(Parameters!$B$9)*NORM.S.INV(RAND()) | F9: =SQRT(Parameters!$B$5)*Factors!F3+SQRT(Parameters!$B$6)*Factors!F8+SQRT(Parameters!$B$7)*Factors!F9+SQRT(Parameters!$B$9)*NORM.S.INV(RAND()) | G9: =SQRT(Parameters!$B$5)*Factors!G3+SQRT(Parameters!$B$6)*Factors!G8+SQRT(Parameters!$B$7)*Factors!G9+SQRT(Parameters!$B$9)*NORM.S.INV(RAND()) | H9: =SQRT(Parameters!$B$5)*Factors!H3+SQRT(Parameters!$B$6)*Factors!H8+SQRT(Parameters!$B$7)*Factors!H9+SQRT(Parameters!$B$9)*NORM.S.INV(RAND()) | I9: =SQRT(Parameters!$B$5)*Factors!I3+SQRT(Parameters!$B$6)*Factors!I8+SQRT(Parameters!$B$7)*Factors!I9+SQRT(Parameters!$B$9)*NORM.S.INV(RAND()) | ... SG9: =SQRT(Parameters!$B$5)*Factors!SG3+SQRT(Parameters!$B$6)*Factors!SG8+SQRT(Parameters!$B$7)*Factors!SG9+SQRT(Parameters!$B$9)*NORM.S.INV(RAND())
A10: OBL-009 | B10: =SQRT(Parameters!$B$5)*Factors!B3+SQRT(Parameters!$B$6)*Factors!B7+SQRT(Parameters!$B$7)*Factors!B10+SQRT(Parameters!$B$9)*NORM.S.INV(RAND()) | C10: =SQRT(Parameters!$B$5)*Factors!C3+SQRT(Parameters!$B$6)*Factors!C7+SQRT(Parameters!$B$7)*Factors!C10+SQRT(Parameters!$B$9)*NORM.S.INV(RAND()) | D10: =SQRT(Parameters!$B$5)*Factors!D3+SQRT(Parameters!$B$6)*Factors!D7+SQRT(Parameters!$B$7)*Factors!D10+SQRT(Parameters!$B$9)*NORM.S.INV(RAND()) | E10: =SQRT(Parameters!$B$5)*Factors!E3+SQRT(Parameters!$B$6)*Factors!E7+SQRT(Parameters!$B$7)*Factors!E10+SQRT(Parameters!$B$9)*NORM.S.INV(RAND()) | F10: =SQRT(Parameters!$B$5)*Factors!F3+SQRT(Parameters!$B$6)*Factors!F7+SQRT(Parameters!$B$7)*Factors!F10+SQRT(Parameters!$B$9)*NORM.S.INV(RAND()) | G10: =SQRT(Parameters!$B$5)*Factors!G3+SQRT(Parameters!$B$6)*Factors!G7+SQRT(Parameters!$B$7)*Factors!G10+SQRT(Parameters!$B$9)*NORM.S.INV(RAND()) | H10: =SQRT(Parameters!$B$5)*Factors!H3+SQRT(Parameters!$B$6)*Factors!H7+SQRT(Parameters!$B$7)*Factors!H10+SQRT(Parameters!$B$9)*NORM.S.INV(RAND()) | I10: =SQRT(Parameters!$B$5)*Factors!I3+SQRT(Parameters!$B$6)*Factors!I7+SQRT(Parameters!$B$7)*Factors!I10+SQRT(Parameters!$B$9)*NORM.S.INV(RAND()) | ... SG10: =SQRT(Parameters!$B$5)*Factors!SG3+SQRT(Parameters!$B$6)*Factors!SG7+SQRT(Parameters!$B$7)*Factors!SG10+SQRT(Parameters!$B$9)*NORM.S.INV(RAND())
A11: OBL-010 | B11: =SQRT(Parameters!$B$5)*Factors!B3+SQRT(Parameters!$B$6)*Factors!B6+SQRT(Parameters!$B$7)*Factors!B9+SQRT(Parameters!$B$9)*NORM.S.INV(RAND()) | C11: =SQRT(Parameters!$B$5)*Factors!C3+SQRT(Parameters!$B$6)*Factors!C6+SQRT(Parameters!$B$7)*Factors!C9+SQRT(Parameters!$B$9)*NORM.S.INV(RAND()) | D11: =SQRT(Parameters!$B$5)*Factors!D3+SQRT(Parameters!$B$6)*Factors!D6+SQRT(Parameters!$B$7)*Factors!D9+SQRT(Parameters!$B$9)*NORM.S.INV(RAND()) | E11: =SQRT(Parameters!$B$5)*Factors!E3+SQRT(Parameters!$B$6)*Factors!E6+SQRT(Parameters!$B$7)*Factors!E9+SQRT(Parameters!$B$9)*NORM.S.INV(RAND()) | F11: =SQRT(Parameters!$B$5)*Factors!F3+SQRT(Parameters!$B$6)*Factors!F6+SQRT(Parameters!$B$7)*Factors!F9+SQRT(Parameters!$B$9)*NORM.S.INV(RAND()) | G11: =SQRT(Parameters!$B$5)*Factors!G3+SQRT(Parameters!$B$6)*Factors!G6+SQRT(Parameters!$B$7)*Factors!G9+SQRT(Parameters!$B$9)*NORM.S.INV(RAND()) | H11: =SQRT(Parameters!$B$5)*Factors!H3+SQRT(Parameters!$B$6)*Factors!H6+SQRT(Parameters!$B$7)*Factors!H9+SQRT(Parameters!$B$9)*NORM.S.INV(RAND()) | I11: =SQRT(Parameters!$B$5)*Factors!I3+SQRT(Parameters!$B$6)*Factors!I6+SQRT(Parameters!$B$7)*Factors!I9+SQRT(Parameters!$B$9)*NORM.S.INV(RAND()) | ... SG11: =SQRT(Parameters!$B$5)*Factors!SG3+SQRT(Parameters!$B$6)*Factors!SG6+SQRT(Parameters!$B$7)*Factors!SG9+SQRT(Parameters!$B$9)*NORM.S.INV(RAND())
A12: OBL-011 | B12: =SQRT(Parameters!$B$5)*Factors!B4+SQRT(Parameters!$B$6)*Factors!B5+SQRT(Parameters!$B$7)*Factors!B9+SQRT(Parameters!$B$9)*NORM.S.INV(RAND()) | C12: =SQRT(Parameters!$B$5)*Factors!C4+SQRT(Parameters!$B$6)*Factors!C5+SQRT(Parameters!$B$7)*Factors!C9+SQRT(Parameters!$B$9)*NORM.S.INV(RAND()) | D12: =SQRT(Parameters!$B$5)*Factors!D4+SQRT(Parameters!$B$6)*Factors!D5+SQRT(Parameters!$B$7)*Factors!D9+SQRT(Parameters!$B$9)*NORM.S.INV(RAND()) | E12: =SQRT(Parameters!$B$5)*Factors!E4+SQRT(Parameters!$B$6)*Factors!E5+SQRT(Parameters!$B$7)*Factors!E9+SQRT(Parameters!$B$9)*NORM.S.INV(RAND()) | F12: =SQRT(Parameters!$B$5)*Factors!F4+SQRT(Parameters!$B$6)*Factors!F5+SQRT(Parameters!$B$7)*Factors!F9+SQRT(Parameters!$B$9)*NORM.S.INV(RAND()) | G12: =SQRT(Parameters!$B$5)*Factors!G4+SQRT(Parameters!$B$6)*Factors!G5+SQRT(Parameters!$B$7)*Factors!G9+SQRT(Parameters!$B$9)*NORM.S.INV(RAND()) | H12: =SQRT(Parameters!$B$5)*Factors!H4+SQRT(Parameters!$B$6)*Factors!H5+SQRT(Parameters!$B$7)*Factors!H9+SQRT(Parameters!$B$9)*NORM.S.INV(RAND()) | I12: =SQRT(Parameters!$B$5)*Factors!I4+SQRT(Parameters!$B$6)*Factors!I5+SQRT(Parameters!$B$7)*Factors!I9+SQRT(Parameters!$B$9)*NORM.S.INV(RAND()) | ... SG12: =SQRT(Parameters!$B$5)*Factors!SG4+SQRT(Parameters!$B$6)*Factors!SG5+SQRT(Parameters!$B$7)*Factors!SG9+SQRT(Parameters!$B$9)*NORM.S.INV(RAND())
A13: OBL-012 | B13: =SQRT(Parameters!$B$5)*Factors!B4+SQRT(Parameters!$B$6)*Factors!B7+SQRT(Parameters!$B$7)*Factors!B9+SQRT(Parameters!$B$9)*NORM.S.INV(RAND()) | C13: =SQRT(Parameters!$B$5)*Factors!C4+SQRT(Parameters!$B$6)*Factors!C7+SQRT(Parameters!$B$7)*Factors!C9+SQRT(Parameters!$B$9)*NORM.S.INV(RAND()) | D13: =SQRT(Parameters!$B$5)*Factors!D4+SQRT(Parameters!$B$6)*Factors!D7+SQRT(Parameters!$B$7)*Factors!D9+SQRT(Parameters!$B$9)*NORM.S.INV(RAND()) | E13: =SQRT(Parameters!$B$5)*Factors!E4+SQRT(Parameters!$B$6)*Factors!E7+SQRT(Parameters!$B$7)*Factors!E9+SQRT(Parameters!$B$9)*NORM.S.INV(RAND()) | F13: =SQRT(Parameters!$B$5)*Factors!F4+SQRT(Parameters!$B$6)*Factors!F7+SQRT(Parameters!$B$7)*Factors!F9+SQRT(Parameters!$B$9)*NORM.S.INV(RAND()) | G13: =SQRT(Parameters!$B$5)*Factors!G4+SQRT(Parameters!$B$6)*Factors!G7+SQRT(Parameters!$B$7)*Factors!G9+SQRT(Parameters!$B$9)*NORM.S.INV(RAND()) | H13: =SQRT(Parameters!$B$5)*Factors!H4+SQRT(Parameters!$B$6)*Factors!H7+SQRT(Parameters!$B$7)*Factors!H9+SQRT(Parameters!$B$9)*NORM.S.INV(RAND()) | I13: =SQRT(Parameters!$B$5)*Factors!I4+SQRT(Parameters!$B$6)*Factors!I7+SQRT(Parameters!$B$7)*Factors!I9+SQRT(Parameters!$B$9)*NORM.S.INV(RAND()) | ... SG13: =SQRT(Parameters!$B$5)*Factors!SG4+SQRT(Parameters!$B$6)*Factors!SG7+SQRT(Parameters!$B$7)*Factors!SG9+SQRT(Parameters!$B$9)*NORM.S.INV(RAND())
A14: OBL-013 | B14: =SQRT(Parameters!$B$5)*Factors!B4+SQRT(Parameters!$B$6)*Factors!B8+SQRT(Parameters!$B$7)*Factors!B10+SQRT(Parameters!$B$9)*NORM.S.INV(RAND()) | C14: =SQRT(Parameters!$B$5)*Factors!C4+SQRT(Parameters!$B$6)*Factors!C8+SQRT(Parameters!$B$7)*Factors!C10+SQRT(Parameters!$B$9)*NORM.S.INV(RAND()) | D14: =SQRT(Parameters!$B$5)*Factors!D4+SQRT(Parameters!$B$6)*Factors!D8+SQRT(Parameters!$B$7)*Factors!D10+SQRT(Parameters!$B$9)*NORM.S.INV(RAND()) | E14: =SQRT(Parameters!$B$5)*Factors!E4+SQRT(Parameters!$B$6)*Factors!E8+SQRT(Parameters!$B$7)*Factors!E10+SQRT(Parameters!$B$9)*NORM.S.INV(RAND()) | F14: =SQRT(Parameters!$B$5)*Factors!F4+SQRT(Parameters!$B$6)*Factors!F8+SQRT(Parameters!$B$7)*Factors!F10+SQRT(Parameters!$B$9)*NORM.S.INV(RAND()) | G14: =SQRT(Parameters!$B$5)*Factors!G4+SQRT(Parameters!$B$6)*Factors!G8+SQRT(Parameters!$B$7)*Factors!G10+SQRT(Parameters!$B$9)*NORM.S.INV(RAND()) | H14: =SQRT(Parameters!$B$5)*Factors!H4+SQRT(Parameters!$B$6)*Factors!H8+SQRT(Parameters!$B$7)*Factors!H10+SQRT(Parameters!$B$9)*NORM.S.INV(RAND()) | I14: =SQRT(Parameters!$B$5)*Factors!I4+SQRT(Parameters!$B$6)*Factors!I8+SQRT(Parameters!$B$7)*Factors!I10+SQRT(Parameters!$B$9)*NORM.S.INV(RAND()) | ... SG14: =SQRT(Parameters!$B$5)*Factors!SG4+SQRT(Parameters!$B$6)*Factors!SG8+SQRT(Parameters!$B$7)*Factors!SG10+SQRT(Parameters!$B$9)*NORM.S.INV(RAND())
A15: OBL-014 | B15: =SQRT(Parameters!$B$5)*Factors!B4+SQRT(Parameters!$B$6)*Factors!B5+SQRT(Parameters!$B$7)*Factors!B10+SQRT(Parameters!$B$9)*NORM.S.INV(RAND()) | C15: =SQRT(Parameters!$B$5)*Factors!C4+SQRT(Parameters!$B$6)*Factors!C5+SQRT(Parameters!$B$7)*Factors!C10+SQRT(Parameters!$B$9)*NORM.S.INV(RAND()) | D15: =SQRT(Parameters!$B$5)*Factors!D4+SQRT(Parameters!$B$6)*Factors!D5+SQRT(Parameters!$B$7)*Factors!D10+SQRT(Parameters!$B$9)*NORM.S.INV(RAND()) | E15: =SQRT(Parameters!$B$5)*Factors!E4+SQRT(Parameters!$B$6)*Factors!E5+SQRT(Parameters!$B$7)*Factors!E10+SQRT(Parameters!$B$9)*NORM.S.INV(RAND()) | F15: =SQRT(Parameters!$B$5)*Factors!F4+SQRT(Parameters!$B$6)*Factors!F5+SQRT(Parameters!$B$7)*Factors!F10+SQRT(Parameters!$B$9)*NORM.S.INV(RAND()) | G15: =SQRT(Parameters!$B$5)*Factors!G4+SQRT(Parameters!$B$6)*Factors!G5+SQRT(Parameters!$B$7)*Factors!G10+SQRT(Parameters!$B$9)*NORM.S.INV(RAND()) | H15: =SQRT(Parameters!$B$5)*Factors!H4+SQRT(Parameters!$B$6)*Factors!H5+SQRT(Parameters!$B$7)*Factors!H10+SQRT(Parameters!$B$9)*NORM.S.INV(RAND()) | I15: =SQRT(Parameters!$B$5)*Factors!I4+SQRT(Parameters!$B$6)*Factors!I5+SQRT(Parameters!$B$7)*Factors!I10+SQRT(Parameters!$B$9)*NORM.S.INV(RAND()) | ... SG15: =SQRT(Parameters!$B$5)*Factors!SG4+SQRT(Parameters!$B$6)*Factors!SG5+SQRT(Parameters!$B$7)*Factors!SG10+SQRT(Parameters!$B$9)*NORM.S.INV(RAND())
A16: OBL-015 | B16: =SQRT(Parameters!$B$5)*Factors!B4+SQRT(Parameters!$B$6)*Factors!B6+SQRT(Parameters!$B$7)*Factors!B10+SQRT(Parameters!$B$9)*NORM.S.INV(RAND()) | C16: =SQRT(Parameters!$B$5)*Factors!C4+SQRT(Parameters!$B$6)*Factors!C6+SQRT(Parameters!$B$7)*Factors!C10+SQRT(Parameters!$B$9)*NORM.S.INV(RAND()) | D16: =SQRT(Parameters!$B$5)*Factors!D4+SQRT(Parameters!$B$6)*Factors!D6+SQRT(Parameters!$B$7)*Factors!D10+SQRT(Parameters!$B$9)*NORM.S.INV(RAND()) | E16: =SQRT(Parameters!$B$5)*Factors!E4+SQRT(Parameters!$B$6)*Factors!E6+SQRT(Parameters!$B$7)*Factors!E10+SQRT(Parameters!$B$9)*NORM.S.INV(RAND()) | F16: =SQRT(Parameters!$B$5)*Factors!F4+SQRT(Parameters!$B$6)*Factors!F6+SQRT(Parameters!$B$7)*Factors!F10+SQRT(Parameters!$B$9)*NORM.S.INV(RAND()) | G16: =SQRT(Parameters!$B$5)*Factors!G4+SQRT(Parameters!$B$6)*Factors!G6+SQRT(Parameters!$B$7)*Factors!G10+SQRT(Parameters!$B$9)*NORM.S.INV(RAND()) | H16: =SQRT(Parameters!$B$5)*Factors!H4+SQRT(Parameters!$B$6)*Factors!H6+SQRT(Parameters!$B$7)*Factors!H10+SQRT(Parameters!$B$9)*NORM.S.INV(RAND()) | I16: =SQRT(Parameters!$B$5)*Factors!I4+SQRT(Parameters!$B$6)*Factors!I6+SQRT(Parameters!$B$7)*Factors!I10+SQRT(Parameters!$B$9)*NORM.S.INV(RAND()) | ... SG16: =SQRT(Parameters!$B$5)*Factors!SG4+SQRT(Parameters!$B$6)*Factors!SG6+SQRT(Parameters!$B$7)*Factors!SG10+SQRT(Parameters!$B$9)*NORM.S.INV(RAND())

Sheet Defaults
A1: Obligor \ Trial | B1: Trial 1 | C1: Trial 2 | D1: Trial 3 | E1: Trial 4 | F1: Trial 5 | G1: Trial 6 | H1: Trial 7 | I1: Trial 8 | J1: Trial 9 | K1: Trial 10 | L1: Trial 11 | M1: Trial 12 | N1: Trial 13 | O1: Trial 14 | P1: Trial 15 | Q1: Trial 16 | R1: Trial 17 | S1: Trial 18 | T1: Trial 19 | U1: Trial 20 | V1: Trial 21 | W1: Trial 22 | X1: Trial 23 | Y1: Trial 24 | Z1: Trial 25 | AA1: Trial 26 | AB1: Trial 27 | AC1: Trial 28 | AD1: Trial 29 | AE1: Trial 30 | AF1: Trial 31 | AG1: Trial 32 | AH1: Trial 33 | AI1: Trial 34 | AJ1: Trial 35 | AK1: Trial 36 | AL1: Trial 37 | AM1: Trial 38 | AN1: Trial 39 | AO1: Trial 40 | AP1: Trial 41 | AQ1: Trial 42 | AR1: Trial 43 | AS1: Trial 44 | AT1: Trial 45 | AU1: Trial 46 | AV1: Trial 47 | AW1: Trial 48 | AX1: Trial 49 | AY1: Trial 50 | AZ1: Trial 51 | BA1: Trial 52 | BB1: Trial 53 | BC1: Trial 54 | BD1: Trial 55 | BE1: Trial 56 | BF1: Trial 57 | BG1: Trial 58 | BH1: Trial 59 | BI1: Trial 60 | BJ1: Trial 61 | BK1: Trial 62 | BL1: Trial 63 | BM1: Trial 64 | BN1: Trial 65 | BO1: Trial 66 | BP1: Trial 67 | BQ1: Trial 68 | BR1: Trial 69 | BS1: Trial 70 | BT1: Trial 71 | BU1: Trial 72 | BV1: Trial 73 | BW1: Trial 74 | BX1: Trial 75 | BY1: Trial 76 | BZ1: Trial 77 | CA1: Trial 78 | CB1: Trial 79 | CC1: Trial 80 | CD1: Trial 81 | CE1: Trial 82 | CF1: Trial 83 | CG1: Trial 84 | CH1: Trial 85 | CI1: Trial 86 | CJ1: Trial 87 | CK1: Trial 88 | CL1: Trial 89 | CM1: Trial 90 | CN1: Trial 91 | CO1: Trial 92 | CP1: Trial 93 | CQ1: Trial 94 | CR1: Trial 95 | CS1: Trial 96 | CT1: Trial 97 | CU1: Trial 98 | CV1: Trial 99 | CW1: Trial 100 | CX1: Trial 101 | CY1: Trial 102 | CZ1: Trial 103 | DA1: Trial 104 | DB1: Trial 105 | DC1: Trial 106 | DD1: Trial 107 | DE1: Trial 108 | DF1: Trial 109 | DG1: Trial 110 | DH1: Trial 111 | DI1: Trial 112 | DJ1: Trial 113 | DK1: Trial 114 | DL1: Trial 115 | DM1: Trial 116 | DN1: Trial 117 | DO1: Trial 118 | DP1: Trial 119 | DQ1: Trial 120 | DR1: Trial 121 | DS1: Trial 122 | DT1: Trial 123 | DU1: Trial 124 | DV1: Trial 125 | DW1: Trial 126 | DX1: Trial 127 | DY1: Trial 128 | DZ1: Trial 129 | EA1: Trial 130 | EB1: Trial 131 | EC1: Trial 132 | ED1: Trial 133 | EE1: Trial 134 | EF1: Trial 135 | EG1: Trial 136 | EH1: Trial 137 | EI1: Trial 138 | EJ1: Trial 139 | EK1: Trial 140 | EL1: Trial 141 | EM1: Trial 142 | EN1: Trial 143 | EO1: Trial 144 | EP1: Trial 145 | EQ1: Trial 146 | ER1: Trial 147 | ES1: Trial 148 | ET1: Trial 149 | EU1: Trial 150 | EV1: Trial 151 | EW1: Trial 152 | EX1: Trial 153 | EY1: Trial 154 | EZ1: Trial 155 | FA1: Trial 156 | FB1: Trial 157 | FC1: Trial 158 | FD1: Trial 159 | FE1: Trial 160 | FF1: Trial 161 | FG1: Trial 162 | FH1: Trial 163 | FI1: Trial 164 | FJ1: Trial 165 | FK1: Trial 166 | FL1: Trial 167 | FM1: Trial 168 | FN1: Trial 169 | FO1: Trial 170 | FP1: Trial 171 | FQ1: Trial 172 | FR1: Trial 173 | FS1: Trial 174 | FT1: Trial 175 | FU1: Trial 176 | FV1: Trial 177 | FW1: Trial 178 | FX1: Trial 179 | FY1: Trial 180 | FZ1: Trial 181 | GA1: Trial 182 | GB1: Trial 183 | GC1: Trial 184 | GD1: Trial 185 | GE1: Trial 186 | GF1: Trial 187 | GG1: Trial 188 | GH1: Trial 189 | GI1: Trial 190 | GJ1: Trial 191 | GK1: Trial 192 | GL1: Trial 193 | GM1: Trial 194 | GN1: Trial 195 | GO1: Trial 196 | GP1: Trial 197 | GQ1: Trial 198 | GR1: Trial 199 | GS1: Trial 200 | GT1: Trial 201 | GU1: Trial 202 | GV1: Trial 203 | GW1: Trial 204 | GX1: Trial 205 | GY1: Trial 206 | GZ1: Trial 207 | HA1: Trial 208 | HB1: Trial 209 | HC1: Trial 210 | HD1: Trial 211 | HE1: Trial 212 | HF1: Trial 213 | HG1: Trial 214 | HH1: Trial 215 | HI1: Trial 216 | HJ1: Trial 217 | HK1: Trial 218 | HL1: Trial 219 | HM1: Trial 220 | HN1: Trial 221 | HO1: Trial 222 | HP1: Trial 223 | HQ1: Trial 224 | HR1: Trial 225 | HS1: Trial 226 | HT1: Trial 227 | HU1: Trial 228 | HV1: Trial 229 | HW1: Trial 230 | HX1: Trial 231 | HY1: Trial 232 | HZ1: Trial 233 | IA1: Trial 234 | IB1: Trial 235 | IC1: Trial 236 | ID1: Trial 237 | IE1: Trial 238 | IF1: Trial 239 | IG1: Trial 240 | IH1: Trial 241 | II1: Trial 242 | IJ1: Trial 243 | IK1: Trial 244 | IL1: Trial 245 | IM1: Trial 246 | IN1: Trial 247 | IO1: Trial 248 | IP1: Trial 249 | IQ1: Trial 250 | IR1: Trial 251 | IS1: Trial 252 | IT1: Trial 253 | IU1: Trial 254 | IV1: Trial 255 | IW1: Trial 256 | IX1: Trial 257 | IY1: Trial 258 | IZ1: Trial 259 | JA1: Trial 260 | JB1: Trial 261 | JC1: Trial 262 | JD1: Trial 263 | JE1: Trial 264 | JF1: Trial 265 | JG1: Trial 266 | JH1: Trial 267 | JI1: Trial 268 | JJ1: Trial 269 | JK1: Trial 270 | JL1: Trial 271 | JM1: Trial 272 | JN1: Trial 273 | JO1: Trial 274 | JP1: Trial 275 | JQ1: Trial 276 | JR1: Trial 277 | JS1: Trial 278 | JT1: Trial 279 | JU1: Trial 280 | JV1: Trial 281 | JW1: Trial 282 | JX1: Trial 283 | JY1: Trial 284 | JZ1: Trial 285 | KA1: Trial 286 | KB1: Trial 287 | KC1: Trial 288 | KD1: Trial 289 | KE1: Trial 290 | KF1: Trial 291 | KG1: Trial 292 | KH1: Trial 293 | KI1: Trial 294 | KJ1: Trial 295 | KK1: Trial 296 | KL1: Trial 297 | KM1: Trial 298 | KN1: Trial 299 | KO1: Trial 300 | KP1: Trial 301 | KQ1: Trial 302 | KR1: Trial 303 | KS1: Trial 304 | KT1: Trial 305 | KU1: Trial 306 | KV1: Trial 307 | KW1: Trial 308 | KX1: Trial 309 | KY1: Trial 310 | KZ1: Trial 311 | LA1: Trial 312 | LB1: Trial 313 | LC1: Trial 314 | LD1: Trial 315 | LE1: Trial 316 | LF1: Trial 317 | LG1: Trial 318 | LH1: Trial 319 | LI1: Trial 320 | LJ1: Trial 321 | LK1: Trial 322 | LL1: Trial 323 | LM1: Trial 324 | LN1: Trial 325 | LO1: Trial 326 | LP1: Trial 327 | LQ1: Trial 328 | LR1: Trial 329 | LS1: Trial 330 | LT1: Trial 331 | LU1: Trial 332 | LV1: Trial 333 | LW1: Trial 334 | LX1: Trial 335 | LY1: Trial 336 | LZ1: Trial 337 | MA1: Trial 338 | MB1: Trial 339 | MC1: Trial 340 | MD1: Trial 341 | ME1: Trial 342 | MF1: Trial 343 | MG1: Trial 344 | MH1: Trial 345 | MI1: Trial 346 | MJ1: Trial 347 | MK1: Trial 348 | ML1: Trial 349 | MM1: Trial 350 | MN1: Trial 351 | MO1: Trial 352 | MP1: Trial 353 | MQ1: Trial 354 | MR1: Trial 355 | MS1: Trial 356 | MT1: Trial 357 | MU1: Trial 358 | MV1: Trial 359 | MW1: Trial 360 | MX1: Trial 361 | MY1: Trial 362 | MZ1: Trial 363 | NA1: Trial 364 | NB1: Trial 365 | NC1: Trial 366 | ND1: Trial 367 | NE1: Trial 368 | NF1: Trial 369 | NG1: Trial 370 | NH1: Trial 371 | NI1: Trial 372 | NJ1: Trial 373 | NK1: Trial 374 | NL1: Trial 375 | NM1: Trial 376 | NN1: Trial 377 | NO1: Trial 378 | NP1: Trial 379 | NQ1: Trial 380 | NR1: Trial 381 | NS1: Trial 382 | NT1: Trial 383 | NU1: Trial 384 | NV1: Trial 385 | NW1: Trial 386 | NX1: Trial 387 | NY1: Trial 388 | NZ1: Trial 389 | OA1: Trial 390 | OB1: Trial 391 | OC1: Trial 392 | OD1: Trial 393 | OE1: Trial 394 | OF1: Trial 395 | OG1: Trial 396 | OH1: Trial 397 | OI1: Trial 398 | OJ1: Trial 399 | OK1: Trial 400 | OL1: Trial 401 | OM1: Trial 402 | ON1: Trial 403 | OO1: Trial 404 | OP1: Trial 405 | OQ1: Trial 406 | OR1: Trial 407 | OS1: Trial 408 | OT1: Trial 409 | OU1: Trial 410 | OV1: Trial 411 | OW1: Trial 412 | OX1: Trial 413 | OY1: Trial 414 | OZ1: Trial 415 | PA1: Trial 416 | PB1: Trial 417 | PC1: Trial 418 | PD1: Trial 419 | PE1: Trial 420 | PF1: Trial 421 | PG1: Trial 422 | PH1: Trial 423 | PI1: Trial 424 | PJ1: Trial 425 | PK1: Trial 426 | PL1: Trial 427 | PM1: Trial 428 | PN1: Trial 429 | PO1: Trial 430 | PP1: Trial 431 | PQ1: Trial 432 | PR1: Trial 433 | PS1: Trial 434 | PT1: Trial 435 | PU1: Trial 436 | PV1: Trial 437 | PW1: Trial 438 | PX1: Trial 439 | PY1: Trial 440 | PZ1: Trial 441 | QA1: Trial 442 | QB1: Trial 443 | QC1: Trial 444 | QD1: Trial 445 | QE1: Trial 446 | QF1: Trial 447 | QG1: Trial 448 | QH1: Trial 449 | QI1: Trial 450 | QJ1: Trial 451 | QK1: Trial 452 | QL1: Trial 453 | QM1: Trial 454 | QN1: Trial 455 | QO1: Trial 456 | QP1: Trial 457 | QQ1: Trial 458 | QR1: Trial 459 | QS1: Trial 460 | QT1: Trial 461 | QU1: Trial 462 | QV1: Trial 463 | QW1: Trial 464 | QX1: Trial 465 | QY1: Trial 466 | QZ1: Trial 467 | RA1: Trial 468 | RB1: Trial 469 | RC1: Trial 470 | RD1: Trial 471 | RE1: Trial 472 | RF1: Trial 473 | RG1: Trial 474 | RH1: Trial 475 | RI1: Trial 476 | RJ1: Trial 477 | RK1: Trial 478 | RL1: Trial 479 | RM1: Trial 480 | RN1: Trial 481 | RO1: Trial 482 | RP1: Trial 483 | RQ1: Trial 484 | RR1: Trial 485 | RS1: Trial 486 | RT1: Trial 487 | RU1: Trial 488 | RV1: Trial 489 | RW1: Trial 490 | RX1: Trial 491 | RY1: Trial 492 | RZ1: Trial 493 | SA1: Trial 494 | SB1: Trial 495 | SC1: Trial 496 | SD1: Trial 497 | SE1: Trial 498 | SF1: Trial 499 | SG1: Trial 500
A2: OBL-001 | B2: =IF(Simulation!B2<Obligors!$I$2,1,0) | C2: =IF(Simulation!C2<Obligors!$I$2,1,0) | D2: =IF(Simulation!D2<Obligors!$I$2,1,0) | E2: =IF(Simulation!E2<Obligors!$I$2,1,0) | F2: =IF(Simulation!F2<Obligors!$I$2,1,0) | G2: =IF(Simulation!G2<Obligors!$I$2,1,0) | H2: =IF(Simulation!H2<Obligors!$I$2,1,0) | I2: =IF(Simulation!I2<Obligors!$I$2,1,0) | ... SG2: =IF(Simulation!SG2<Obligors!$I$2,1,0)
A3: OBL-002 | B3: =IF(Simulation!B3<Obligors!$I$3,1,0) | C3: =IF(Simulation!C3<Obligors!$I$3,1,0) | D3: =IF(Simulation!D3<Obligors!$I$3,1,0) | E3: =IF(Simulation!E3<Obligors!$I$3,1,0) | F3: =IF(Simulation!F3<Obligors!$I$3,1,0) | G3: =IF(Simulation!G3<Obligors!$I$3,1,0) | H3: =IF(Simulation!H3<Obligors!$I$3,1,0) | I3: =IF(Simulation!I3<Obligors!$I$3,1,0) | ... SG3: =IF(Simulation!SG3<Obligors!$I$3,1,0)
A4: OBL-003 | B4: =IF(Simulation!B4<Obligors!$I$4,1,0) | C4: =IF(Simulation!C4<Obligors!$I$4,1,0) | D4: =IF(Simulation!D4<Obligors!$I$4,1,0) | E4: =IF(Simulation!E4<Obligors!$I$4,1,0) | F4: =IF(Simulation!F4<Obligors!$I$4,1,0) | G4: =IF(Simulation!G4<Obligors!$I$4,1,0) | H4: =IF(Simulation!H4<Obligors!$I$4,1,0) | I4: =IF(Simulation!I4<Obligors!$I$4,1,0) | ... SG4: =IF(Simulation!SG4<Obligors!$I$4,1,0)
A5: OBL-004 | B5: =IF(Simulation!B5<Obligors!$I$5,1,0) | C5: =IF(Simulation!C5<Obligors!$I$5,1,0) | D5: =IF(Simulation!D5<Obligors!$I$5,1,0) | E5: =IF(Simulation!E5<Obligors!$I$5,1,0) | F5: =IF(Simulation!F5<Obligors!$I$5,1,0) | G5: =IF(Simulation!G5<Obligors!$I$5,1,0) | H5: =IF(Simulation!H5<Obligors!$I$5,1,0) | I5: =IF(Simulation!I5<Obligors!$I$5,1,0) | ... SG5: =IF(Simulation!SG5<Obligors!$I$5,1,0)
A6: OBL-005 | B6: =IF(Simulation!B6<Obligors!$I$6,1,0) | C6: =IF(Simulation!C6<Obligors!$I$6,1,0) | D6: =IF(Simulation!D6<Obligors!$I$6,1,0) | E6: =IF(Simulation!E6<Obligors!$I$6,1,0) | F6: =IF(Simulation!F6<Obligors!$I$6,1,0) | G6: =IF(Simulation!G6<Obligors!$I$6,1,0) | H6: =IF(Simulation!H6<Obligors!$I$6,1,0) | I6: =IF(Simulation!I6<Obligors!$I$6,1,0) | ... SG6: =IF(Simulation!SG6<Obligors!$I$6,1,0)
A7: OBL-006 | B7: =IF(Simulation!B7<Obligors!$I$7,1,0) | C7: =IF(Simulation!C7<Obligors!$I$7,1,0) | D7: =IF(Simulation!D7<Obligors!$I$7,1,0) | E7: =IF(Simulation!E7<Obligors!$I$7,1,0) | F7: =IF(Simulation!F7<Obligors!$I$7,1,0) | G7: =IF(Simulation!G7<Obligors!$I$7,1,0) | H7: =IF(Simulation!H7<Obligors!$I$7,1,0) | I7: =IF(Simulation!I7<Obligors!$I$7,1,0) | ... SG7: =IF(Simulation!SG7<Obligors!$I$7,1,0)
A8: OBL-007 | B8: =IF(Simulation!B8<Obligors!$I$8,1,0) | C8: =IF(Simulation!C8<Obligors!$I$8,1,0) | D8: =IF(Simulation!D8<Obligors!$I$8,1,0) | E8: =IF(Simulation!E8<Obligors!$I$8,1,0) | F8: =IF(Simulation!F8<Obligors!$I$8,1,0) | G8: =IF(Simulation!G8<Obligors!$I$8,1,0) | H8: =IF(Simulation!H8<Obligors!$I$8,1,0) | I8: =IF(Simulation!I8<Obligors!$I$8,1,0) | ... SG8: =IF(Simulation!SG8<Obligors!$I$8,1,0)
A9: OBL-008 | B9: =IF(Simulation!B9<Obligors!$I$9,1,0) | C9: =IF(Simulation!C9<Obligors!$I$9,1,0) | D9: =IF(Simulation!D9<Obligors!$I$9,1,0) | E9: =IF(Simulation!E9<Obligors!$I$9,1,0) | F9: =IF(Simulation!F9<Obligors!$I$9,1,0) | G9: =IF(Simulation!G9<Obligors!$I$9,1,0) | H9: =IF(Simulation!H9<Obligors!$I$9,1,0) | I9: =IF(Simulation!I9<Obligors!$I$9,1,0) | ... SG9: =IF(Simulation!SG9<Obligors!$I$9,1,0)
A10: OBL-009 | B10: =IF(Simulation!B10<Obligors!$I$10,1,0) | C10: =IF(Simulation!C10<Obligors!$I$10,1,0) | D10: =IF(Simulation!D10<Obligors!$I$10,1,0) | E10: =IF(Simulation!E10<Obligors!$I$10,1,0) | F10: =IF(Simulation!F10<Obligors!$I$10,1,0) | G10: =IF(Simulation!G10<Obligors!$I$10,1,0) | H10: =IF(Simulation!H10<Obligors!$I$10,1,0) | I10: =IF(Simulation!I10<Obligors!$I$10,1,0) | ... SG10: =IF(Simulation!SG10<Obligors!$I$10,1,0)
A11: OBL-010 | B11: =IF(Simulation!B11<Obligors!$I$11,1,0) | C11: =IF(Simulation!C11<Obligors!$I$11,1,0) | D11: =IF(Simulation!D11<Obligors!$I$11,1,0) | E11: =IF(Simulation!E11<Obligors!$I$11,1,0) | F11: =IF(Simulation!F11<Obligors!$I$11,1,0) | G11: =IF(Simulation!G11<Obligors!$I$11,1,0) | H11: =IF(Simulation!H11<Obligors!$I$11,1,0) | I11: =IF(Simulation!I11<Obligors!$I$11,1,0) | ... SG11: =IF(Simulation!SG11<Obligors!$I$11,1,0)
A12: OBL-011 | B12: =IF(Simulation!B12<Obligors!$I$12,1,0) | C12: =IF(Simulation!C12<Obligors!$I$12,1,0) | D12: =IF(Simulation!D12<Obligors!$I$12,1,0) | E12: =IF(Simulation!E12<Obligors!$I$12,1,0) | F12: =IF(Simulation!F12<Obligors!$I$12,1,0) | G12: =IF(Simulation!G12<Obligors!$I$12,1,0) | H12: =IF(Simulation!H12<Obligors!$I$12,1,0) | I12: =IF(Simulation!I12<Obligors!$I$12,1,0) | ... SG12: =IF(Simulation!SG12<Obligors!$I$12,1,0)
A13: OBL-012 | B13: =IF(Simulation!B13<Obligors!$I$13,1,0) | C13: =IF(Simulation!C13<Obligors!$I$13,1,0) | D13: =IF(Simulation!D13<Obligors!$I$13,1,0) | E13: =IF(Simulation!E13<Obligors!$I$13,1,0) | F13: =IF(Simulation!F13<Obligors!$I$13,1,0) | G13: =IF(Simulation!G13<Obligors!$I$13,1,0) | H13: =IF(Simulation!H13<Obligors!$I$13,1,0) | I13: =IF(Simulation!I13<Obligors!$I$13,1,0) | ... SG13: =IF(Simulation!SG13<Obligors!$I$13,1,0)
A14: OBL-013 | B14: =IF(Simulation!B14<Obligors!$I$14,1,0) | C14: =IF(Simulation!C14<Obligors!$I$14,1,0) | D14: =IF(Simulation!D14<Obligors!$I$14,1,0) | E14: =IF(Simulation!E14<Obligors!$I$14,1,0) | F14: =IF(Simulation!F14<Obligors!$I$14,1,0) | G14: =IF(Simulation!G14<Obligors!$I$14,1,0) | H14: =IF(Simulation!H14<Obligors!$I$14,1,0) | I14: =IF(Simulation!I14<Obligors!$I$14,1,0) | ... SG14: =IF(Simulation!SG14<Obligors!$I$14,1,0)
A15: OBL-014 | B15: =IF(Simulation!B15<Obligors!$I$15,1,0) | C15: =IF(Simulation!C15<Obligors!$I$15,1,0) | D15: =IF(Simulation!D15<Obligors!$I$15,1,0) | E15: =IF(Simulation!E15<Obligors!$I$15,1,0) | F15: =IF(Simulation!F15<Obligors!$I$15,1,0) | G15: =IF(Simulation!G15<Obligors!$I$15,1,0) | H15: =IF(Simulation!H15<Obligors!$I$15,1,0) | I15: =IF(Simulation!I15<Obligors!$I$15,1,0) | ... SG15: =IF(Simulation!SG15<Obligors!$I$15,1,0)
A16: OBL-015 | B16: =IF(Simulation!B16<Obligors!$I$16,1,0) | C16: =IF(Simulation!C16<Obligors!$I$16,1,0) | D16: =IF(Simulation!D16<Obligors!$I$16,1,0) | E16: =IF(Simulation!E16<Obligors!$I$16,1,0) | F16: =IF(Simulation!F16<Obligors!$I$16,1,0) | G16: =IF(Simulation!G16<Obligors!$I$16,1,0) | H16: =IF(Simulation!H16<Obligors!$I$16,1,0) | I16: =IF(Simulation!I16<Obligors!$I$16,1,0) | ... SG16: =IF(Simulation!SG16<Obligors!$I$16,1,0)

Sheet Losses
